Workbook
Name produkty: #REF!

Sheet ИНСТРУКЦИЯ
A1: ИНСТРУКЦИЯ
A5: SEMIS КАЛЬКУЛЯТОР является инструментом, который служит для еженедельного, а также месячного прогнозирования,
A6: сверки и просмотра отчета затраченных средств SEMIS.
A7: Является месячным отчётом, который необходимо обновлять один раз в неделю.
A9: ЛИСТ - "ПЛАН"
A10: Данный лист служит для прогнозирования месячных расходов по Semis. M. Facility, вписывает в жёлтые поля вид расходов и планируемые деньги.
A11: Затем он может оценить уровень Semis за данный месяц. Данные, введенные в этом листе, только планируемые и не переносятся на другие листы.
A13: ЛИСТ - "SEMIS"
A14: Лист служит для учета расходов, оплаченных через рестораны, так называемым перечислением.
A15: Лист является итоговым по расходам Semis за весь месяц. Данные мы заносим еженедельно только в белые поля.
A16: строка 1,2,3- вносим название ресторана, месяц и количество дней
A17: Строка 8,9- количество недель в месяце и количество дней в не полных неделях месяца
... A32: В начале месяца мы планируем расходы на будующий месяц и вносим фактические данные за предыдущий месяц

Sheet ПЛАН
B1: Планирование SEMIS
B3: Статья SEMIS | C3: Описание расходов | D3: Сумма расходов, руб | E3: Фактический SEMIS
A4: Коммунальные услуги | B4: - Природный газ | E4: =D4 -> 0
B5: - Электричество | E5: =D5 -> 0
B6: - Вода и отопление | E6: =D6 -> 0
B7: - Вывоз мусора | E7: =D7 -> 0
B8: - Техобслуж. помещ. | E8: =D8 -> 0
B9: - Клининговые услуги | E9: =D9 -> 0
C10: сумма | D10: =SUM(D4:D9) -> 0 | E10: =SUM(E4:E9) -> 0
A11: Материалы | B11: МБП | E11: =D11+D12+D13+D14+D15+D16+D17 -> 0
B12: Канцтовары
B13: Униформа
B14: Чистящие средства
B15: Сервис
B16: Прочие
C24: сумма | D24: =SUM(D11:D23) -> 0 | E24: =E11 -> 0
A25: Прочие контролируемые расходы | B25: Услуги связи (телефонная мобильная связь) | E25: =D25 -> 0
C28: сумма | D28: =SUM(D25:D27) -> 0 | E28: =E25 -> 0
B29: Оплата квартиры | E29: =D29+D30+D31 -> 0
C32: сумма | D32: =SUM(D29:D31) -> 0 | E32: =E29 -> 0
B33: Транспортно-экспеиционные | E33: =D33+D34+D35 -> 0
C36: сумма | D36: =SUM(D33:D35) -> 0 | E36: =E33 -> 0
B37: Информационные технологии | E37: =D37+D38+D39+D40+D41 -> 0
C42: сумма | D42: =SUM(D37:D41) -> 0 | E42: =E37 -> 0
B43: Охранные услуги | E43: =D43+D44+D45+D47 -> 0
C48: сумма | D48: =SUM(D43:D47) -> 0 | E48: =E43 -> 0
B49: Командировочные Расходы | E49: =D49+D50+D51 -> 0
C52: сумма | D52: =SUM(D49:D51) -> 0 | E52: =E49 -> 0
B53: Оценка и соблюдение стандартов | E53: =D53+D54+D55 -> 0
C56: сумма | D56: =D53+D54+D55 -> 0 | E56: =E53 -> 0
B57: Лицензионная музыка | E57: =D59 -> 0
C59: сумма | D59: =D57+D58 -> 0 | E59: =E57 -> 0
B60: Пени и штрафы | E60: =D60 -> 0
C62: сумма | D62: =SUM(D60:D61) -> 0 | E62: =E60 -> 0
B63: Консультационно-информац.:юрист | E63: =D64+D63 -> 0
C66: сумма | D66: =D63+D64+D65 -> 0 | E66: =E63 -> 0
B67: Прочие операционные расходы | E67: =D67+D68+D69 -> 0
C70: сумма | D70: =D67+D68+D69 -> 0 | E70: =E67 -> 0
A71: Медкомиссия, санитарные, лабораторные услуги | B71: Медкомиссия | E71: =D71 -> 0
C73: сумма | D73: =SUM(D71:D72) -> 0 | E73: =E71 -> 0
...

Sheet СЧЕТА
A1: 39753
A2: 39783 | E2: 1 | F2: 2 | G2: 3 | H2: 4 | I2: 5 | J2: 6 | K2: 7 | L2: 8 | M2: 9 | N2: 10 | O2: 11 | P2: 12 | Q2: 13 | R2: 14 | S2: 15 | T2: 16 | U2: 17 | V2: 18 | W2: 19 | X2: 20 | Y2: 21 | Z2: 22 | AA2: 23 | AB2: 24 | AC2: 25 | AD2: 26 | AE2: 27 | AF2: 28 | AG2: 29 | AH2: 30 | AI2: 31
A3: 39814
A4: 39845 | D4: АКТУАЛЬНЫЙ МЕСЯЦ: | P4: 38018 | Q4: 38047 | R4: 38078 | S4: 38108 | T4: 38139 | U4: 38169 | V4: 38200 | W4: 38231 | X4: 38261 | Y4: 38292 | Z4: 38322 | AA4: 38353 | AB4: 38384 | AC4: 38412 | AD4: 38443 | AE4: 38473 | AF4: 38504
A5: 39873
A6: 39904 | D6: od: | E6: с: | F6: =DATE(YEAR(E4),MONTH(E4),1) -> 1
A7: 39934 | D7: do: | E7: по: | F7: =DATE(YEAR(F6),MONTH(F6)+1,1)-1 -> 31
A8: 39965
A9: 39995 | E9: Номер ресторана | G9: =#REF! -> #REF!
A10: 40026 | E10: Название ресторана | G10: =#REF! -> #REF!
A11: 40057
A12: 40087
A13: 40118 | E13: 1 | F13: 2 | G13: 3 | H13: 4 | I13: 5 | J13: 6 | K13: 7 | L13: 8 | M13: 9 | N13: 10 | O13: 11 | P13: 12 | Q13: 13 | R13: 14 | S13: 15 | T13: 16 | U13: 17 | V13: 18 | W13: 19 | X13: 20 | Y13: 21 | Z13: 22 | AA13: 23 | AB13: 24 | AC13: 25 | AD13: 26 | AE13: 27 | AF13: 28 | AG13: 29 | AH13: 30 | AI13: 31 | AJ13: 32 | AK13: 33 | AL13: 34 | AM13: 35 | AN13: 36 | AO13: 37 | AP13: 38 | AQ13: 39 | AR13: 40 | AS13: 41 | AT13: 42
A14: 40148 | C14: ;52;53;55;54; | D14: Artykuły techniczne | E14: 0 | F14: 0 | G14: 0 | H14: 0 | I14: 0 | J14: 0 | K14: 0 | L14: 0 | M14: 0 | N14: 0 | O14: 0 | P14: 0 | Q14: 0 | R14: 0 | S14: 0 | T14: 0 | U14: 0 | V14: 0 | W14: 0 | X14: 0 | Y14: 0 | Z14: 0 | AA14: 0 | AB14: 0 | AC14: 0 | AD14: 0 | AE14: 0 | AF14: 0 | AG14: 0 | AH14: 0 | AI14: 0 | AJ14: 0
A15: 40179 | C15: ;30;31;32; | D15: Badania pracownicze | E15: 0 | F15: 0 | G15: 0 | H15: 0 | I15: 0 | J15: 0 | K15: 0 | L15: 0 | M15: 0 | N15: 0 | O15: 0 | P15: 0 | Q15: 0 | R15: 0 | S15: 0 | T15: 0 | U15: 0 | V15: 0 | W15: 0 | X15: 0 | Y15: 0 | Z15: 0 | AA15: 0 | AB15: 0 | AC15: 0 | AD15: 0 | AE15: 0 | AF15: 0 | AG15: 0 | AH15: 0 | AI15: 0 | AJ15: 0
A16: 40210 | C16: ;87;88;89; | D16: Badania jakości usług | E16: 0 | F16: 0 | G16: 0 | H16: 0 | I16: 0 | J16: 0 | K16: 0 | L16: 0 | M16: 0 | N16: 0 | O16: 0 | P16: 0 | Q16: 0 | R16: 0 | S16: 0 | T16: 0 | U16: 0 | V16: 0 | W16: 0 | X16: 0 | Y16: 0 | Z16: 0 | AA16: 0 | AB16: 0 | AC16: 0 | AD16: 0 | AE16: 0 | AF16: 0 | AG16: 0 | AH16: 0 | AI16: 0 | AJ16: 0
A17: 40238 | C17: ;66;67;68; | D17: CO2 | E17: 0 | F17: 0 | G17: 0 | H17: 0 | I17: 0 | J17: 0 | K17: 0 | L17: 0 | M17: 0 | N17: 0 | O17: 0 | P17: 0 | Q17: 0 | R17: 0 | S17: 0 | T17: 0 | U17: 0 | V17: 0 | W17: 0 | X17: 0 | Y17: 0 | Z17: 0 | AA17: 0 | AB17: 0 | AC17: 0 | AD17: 0 | AE17: 0 | AF17: 0 | AG17: 0 | AH17: 0 | AI17: 0 | AJ17: 0
A18: 40269 | C18: ;33; | D18: Fundusz socjalny | E18: 0 | F18: 0 | G18: 0 | H18: 0 | I18: 0 | J18: 0 | K18: 0 | L18: 0 | M18: 0 | N18: 0 | O18: 0 | P18: 0 | Q18: 0 | R18: 0 | S18: 0 | T18: 0 | U18: 0 | V18: 0 | W18: 0 | X18: 0 | Y18: 0 | Z18: 0 | AA18: 0 | AB18: 0 | AC18: 0 | AD18: 0 | AE18: 0 | AF18: 0 | AG18: 0 | AH18: 0 | AI18: 0 | AJ18: 0
A19: 40299 | C19: ;34;35;36; | D19: Imprezy pracownicze | E19: 0 | F19: 0 | G19: 0 | H19: 0 | I19: 0 | J19: 0 | K19: 0 | L19: 0 | M19: 0 | N19: 0 | O19: 0 | P19: 0 | Q19: 0 | R19: 0 | S19: 0 | T19: 0 | U19: 0 | V19: 0 | W19: 0 | X19: 0 | Y19: 0 | Z19: 0 | AA19: 0 | AB19: 0 | AC19: 0 | AD19: 0 | AE19: 0 | AF19: 0 | AG19: 0 | AH19: 0 | AI19: 0 | AJ19: 0
A20: 40330 | C20: ;37;38;39; | D20: Inne benefity | E20: 0 | F20: 0 | G20: 0 | H20: 0 | I20: 0 | J20: 0 | K20: 0 | L20: 0 | M20: 0 | N20: 0 | O20: 0 | P20: 0 | Q20: 0 | R20: 0 | S20: 0 | T20: 0 | U20: 0 | V20: 0 | W20: 0 | X20: 0 | Y20: 0 | Z20: 0 | AA20: 0 | AB20: 0 | AC20: 0 | AD20: 0 | AE20: 0 | AF20: 0 | AG20: 0 | AH20: 0 | AI20: 0 | AJ20: 0
A21: 40360 | C21: ;93;94;95; | D21: Inne usługi | E21: 0 | F21: 0 | G21: 0 | H21: 0 | I21: 0 | J21: 0 | K21: 0 | L21: 0 | M21: 0 | N21: 0 | O21: 0 | P21: 0 | Q21: 0 | R21: 0 | S21: 0 | T21: 0 | U21: 0 | V21: 0 | W21: 0 | X21: 0 | Y21: 0 | Z21: 0 | AA21: 0 | AB21: 0 | AC21: 0 | AD21: 0 | AE21: 0 | AF21: 0 | AG21: 0 | AH21: 0 | AI21: 0 | AJ21: 0
A22: 40391 | C22: ;62; | D22: Kary i grzywny | E22: 0 | F22: 0 | G22: 0 | H22: 0 | I22: 0 | J22: 0 | K22: 0 | L22: 0 | M22: 0 | N22: 0 | O22: 0 | P22: 0 | Q22: 0 | R22: 0 | S22: 0 | T22: 0 | U22: 0 | V22: 0 | W22: 0 | X22: 0 | Y22: 0 | Z22: 0 | AA22: 0 | AB22: 0 | AC22: 0 | AD22: 0 | AE22: 0 | AF22: 0 | AG22: 0 | AH22: 0 | AI22: 0 | AJ22: 0
A23: 40422 | B23: =F6 -> 1 | C23: ;24;25;26; | D23: Kierowcy delivery | E23: 0 | F23: 0 | G23: 0 | H23: 0 | I23: 0 | J23: 0 | K23: 0 | L23: 0 | M23: 0 | N23: 0 | O23: 0 | P23: 0 | Q23: 0 | R23: 0 | S23: 0 | T23: 0 | U23: 0 | V23: 0 | W23: 0 | X23: 0 | Y23: 0 | Z23: 0 | AA23: 0 | AB23: 0 | AC23: 0 | AD23: 0 | AE23: 0 | AF23: 0 | AG23: 0 | AH23: 0 | AI23: 0 | AJ23: 0
A24: 40452 | B24: =F7 -> 31 | C24: ;15;16;17; | D24: Konserwacja budynków | E24: 0 | F24: 0 | G24: 0 | H24: 0 | I24: 0 | J24: 0 | K24: 0 | L24: 0 | M24: 0 | N24: 0 | O24: 0 | P24: 0 | Q24: 0 | R24: 0 | S24: 0 | T24: 0 | U24: 0 | V24: 0 | W24: 0 | X24: 0 | Y24: 0 | Z24: 0 | AA24: 0 | AB24: 0 | AC24: 0 | AD24: 0 | AE24: 0 | AF24: 0 | AG24: 0 | AH24: 0 | AI24: 0 | AJ24: 0
A25: 40483 | B25: =B24-B23+1 -> 31 | C25: ;19;18;20; | D25: Konserwacja urządzeń | E25: 0 | F25: 0 | G25: 0 | H25: 0 | I25: 0 | J25: 0 | K25: 0 | L25: 0 | M25: 0 | N25: 0 | O25: 0 | P25: 0 | Q25: 0 | R25: 0 | S25: 0 | T25: 0 | U25: 0 | V25: 0 | W25: 0 | X25: 0 | Y25: 0 | Z25: 0 | AA25: 0 | AB25: 0 | AC25: 0 | AD25: 0 | AE25: 0 | AF25: 0 | AG25: 0 | AH25: 0 | AI25: 0 | AJ25: 0
A26: 40513 | C26: ;49;50;51; | D26: Konserwacja urządzeń nie gasst. | E26: 0 | F26: 0 | G26: 0 | H26: 0 | I26: 0 | J26: 0 | K26: 0 | L26: 0 | M26: 0 | N26: 0 | O26: 0 | P26: 0 | Q26: 0 | R26: 0 | S26: 0 | T26: 0 | U26: 0 | V26: 0 | W26: 0 | X26: 0 | Y26: 0 | Z26: 0 | AA26: 0 | AB26: 0 | AC26: 0 | AD26: 0 | AE26: 0 | AF26: 0 | AG26: 0 | AH26: 0 | AI26: 0 | AJ26: 0
A27: 40544 | C27: ;102;103;104;105;106;107; | D27: LSM oraz LSM Ice Land | E27: 0 | F27: 0 | G27: 0 | H27: 0 | I27: 0 | J27: 0 | K27: 0 | L27: 0 | M27: 0 | N27: 0 | O27: 0 | P27: 0 | Q27: 0 | R27: 0 | S27: 0 | T27: 0 | U27: 0 | V27: 0 | W27: 0 | X27: 0 | Y27: 0 | Z27: 0 | AA27: 0 | AB27: 0 | AC27: 0 | AD27: 0 | AE27: 0 | AF27: 0 | AG27: 0 | AH27: 0 | AI27: 0 | AJ27: 0
A28: 40575 | C28: ;59;60;61; | D28: Materiały biurowe | E28: 0 | F28: 0 | G28: 0 | H28: 0 | I28: 0 | J28: 0 | K28: 0 | L28: 0 | M28: 0 | N28: 0 | O28: 0 | P28: 0 | Q28: 0 | R28: 0 | S28: 0 | T28: 0 | U28: 0 | V28: 0 | W28: 0 | X28: 0 | Y28: 0 | Z28: 0 | AA28: 0 | AB28: 0 | AC28: 0 | AD28: 0 | AE28: 0 | AF28: 0 | AG28: 0 | AH28: 0 | AI28: 0 | AJ28: 0
A29: 40603 | C29: ;78;79;80; | D29: Naprawa samochodów | E29: 0 | F29: 0 | G29: 0 | H29: 0 | I29: 0 | J29: 0 | K29: 0 | L29: 0 | M29: 0 | N29: 0 | O29: 0 | P29: 0 | Q29: 0 | R29: 0 | S29: 0 | T29: 0 | U29: 0 | V29: 0 | W29: 0 | X29: 0 | Y29: 0 | Z29: 0 | AA29: 0 | AB29: 0 | AC29: 0 | AD29: 0 | AE29: 0 | AF29: 0 | AG29: 0 | AH29: 0 | AI29: 0 | AJ29: 0
A30: 40634 | C30: ;108; | D30: Ocena champs | E30: 0 | F30: 0 | G30: 0 | H30: 0 | I30: 0 | J30: 0 | K30: 0 | L30: 0 | M30: 0 | N30: 0 | O30: 0 | P30: 0 | Q30: 0 | R30: 0 | S30: 0 | T30: 0 | U30: 0 | V30: 0 | W30: 0 | X30: 0 | Y30: 0 | Z30: 0 | AA30: 0 | AB30: 0 | AC30: 0 | AD30: 0 | AE30: 0 | AF30: 0 | AG30: 0 | AH30: 0 | AI30: 0 | AJ30: 0
A31: 40664 | C31: ;63;64;65; | D31: Odszkodowanie dla klienta | E31: 0 | F31: 0 | G31: 0 | H31: 0 | I31: 0 | J31: 0 | K31: 0 | L31: 0 | M31: 0 | N31: 0 | O31: 0 | P31: 0 | Q31: 0 | R31: 0 | S31: 0 | T31: 0 | U31: 0 | V31: 0 | W31: 0 | X31: 0 | Y31: 0 | Z31: 0 | AA31: 0 | AB31: 0 | AC31: 0 | AD31: 0 | AE31: 0 | AF31: 0 | AG31: 0 | AH31: 0 | AI31: 0 | AJ31: 0
A32: 40695 | C32: ;75;76;77; | D32: Odzież ochronna | E32: 0 | F32: 0 | G32: 0 | H32: 0 | I32: 0 | J32: 0 | K32: 0 | L32: 0 | M32: 0 | N32: 0 | O32: 0 | P32: 0 | Q32: 0 | R32: 0 | S32: 0 | T32: 0 | U32: 0 | V32: 0 | W32: 0 | X32: 0 | Y32: 0 | Z32: 0 | AA32: 0 | AB32: 0 | AC32: 0 | AD32: 0 | AE32: 0 | AF32: 0 | AG32: 0 | AH32: 0 | AI32: 0 | AJ32: 0
A33: 40725 | C33: ;43;44;45; | D33: Opłaty urzędowe | E33: 0 | F33: 0 | G33: 0 | H33: 0 | I33: 0 | J33: 0 | K33: 0 | L33: 0 | M33: 0 | N33: 0 | O33: 0 | P33: 0 | Q33: 0 | R33: 0 | S33: 0 | T33: 0 | U33: 0 | V33: 0 | W33: 0 | X33: 0 | Y33: 0 | Z33: 0 | AA33: 0 | AB33: 0 | AC33: 0 | AD33: 0 | AE33: 0 | AF33: 0 | AG33: 0 | AH33: 0 | AI33: 0 | AJ33: 0
A34: 40756 | C34: ;46;47;48; | D34: Opłaty za telefon | E34: 0 | F34: 0 | G34: 0 | H34: 0 | I34: 0 | J34: 0 | K34: 0 | L34: 0 | M34: 0 | N34: 0 | O34: 0 | P34: 0 | Q34: 0 | R34: 0 | S34: 0 | T34: 0 | U34: 0 | V34: 0 | W34: 0 | X34: 0 | Y34: 0 | Z34: 0 | AA34: 0 | AB34: 0 | AC34: 0 | AD34: 0 | AE34: 0 | AF34: 0 | AG34: 0 | AH34: 0 | AI34: 0 | AJ34: 0
A35: 40787 | C35: ;81;82;83; | D35: Paliwo samochodowe | E35: 0 | F35: 0 | G35: 0 | H35: 0 | I35: 0 | J35: 0 | K35: 0 | L35: 0 | M35: 0 | N35: 0 | O35: 0 | P35: 0 | Q35: 0 | R35: 0 | S35: 0 | T35: 0 | U35: 0 | V35: 0 | W35: 0 | X35: 0 | Y35: 0 | Z35: 0 | AA35: 0 | AB35: 0 | AC35: 0 | AD35: 0 | AE35: 0 | AF35: 0 | AG35: 0 | AH35: 0 | AI35: 0 | AJ35: 0
A36: 40817 | C36: ;99;100;101; | D36: Podróże służbowe | E36: 0 | F36: 0 | G36: 0 | H36: 0 | I36: 0 | J36: 0 | K36: 0 | L36: 0 | M36: 0 | N36: 0 | O36: 0 | P36: 0 | Q36: 0 | R36: 0 | S36: 0 | T36: 0 | U36: 0 | V36: 0 | W36: 0 | X36: 0 | Y36: 0 | Z36: 0 | AA36: 0 | AB36: 0 | AC36: 0 | AD36: 0 | AE36: 0 | AF36: 0 | AG36: 0 | AH36: 0 | AI36: 0 | AJ36: 0
A37: 40848 | C37: ;9;91;92; | D37: Rekrutacja pracowników | E37: 0 | F37: 0 | G37: 0 | H37: 0 | I37: 0 | J37: 0 | K37: 0 | L37: 0 | M37: 0 | N37: 0 | O37: 0 | P37: 0 | Q37: 0 | R37: 0 | S37: 0 | T37: 0 | U37: 0 | V37: 0 | W37: 0 | X37: 0 | Y37: 0 | Z37: 0 | AA37: 0 | AB37: 0 | AC37: 0 | AD37: 0 | AE37: 0 | AF37: 0 | AG37: 0 | AH37: 0 | AI37: 0 | AJ37: 0
... A46: 41122 | C46: ;12;13;11;14; | D46: Zywność | E46: 0 | F46: 0 | G46: 0 | H46: 0 | I46: 0 | J46: 0 | K46: 0 | L46: 0 | M46: 0 | N46: 0 | O46: 0 | P46: 0 | Q46: 0 | R46: 0 | S46: 0 | T46: 0 | U46: 0 | V46: 0 | W46: 0 | X46: 0 | Y46: 0 | Z46: 0 | AA46: 0 | AB46: 0 | AC46: 0 | AD46: 0 | AE46: 0 | AF46: 0 | AG46: 0 | AH46: 0 | AI46: 0 | AJ46: 0
A47: 41153
A48: 41183 | E48: =E6 -> с: | F48: =$E$6+E13 -> #VALUE! | G48: =$E$6+F13 -> #VALUE! | H48: =$E$6+G13 -> #VALUE! | I48: =$E$6+H13 -> #VALUE! | J48: =$E$6+I13 -> #VALUE! | K48: =$E$6+J13 -> #VALUE! | L48: =$E$6+K13 -> #VALUE! | M48: =$E$6+L13 -> #VALUE! | ... AT48: =$E$6+AS13 -> #VALUE!
...

Sheet TEMP
C2: ФАКТ | D2: =#REF! -> #REF! | E2: =#REF! -> #REF! | F2: =#REF! -> #REF! | G2: =#REF! -> #REF! | H2: =#REF! -> #REF! | J2: =#REF! -> #REF! | K2: СУММА | L2: множитель | M2: множитель | N2: множитель | O2: множитель | P2: множитель | Q2: множитель
B3: - Природный газ | C3: =#REF! -> #REF! | D3: =#REF! -> #REF! | E3: =#REF! -> #REF! | F3: =#REF! -> #REF! | G3: =#REF! -> #REF! | H3: =#REF! -> #REF! | I3: =#REF!/(#REF!-#REF!) -> #REF! | J3: =#REF! -> #REF! | K3: =C3/#REF! -> #REF! | L3: =K3*#REF!+D3 -> #REF! | M3: =K3*#REF!+E3 -> #REF! | N3: =K3*#REF!+F3 -> #REF! | O3: =K3*#REF!+G3 -> #REF! | P3: =K3*#REF!+H3 -> #REF! | Q3: =K3*#REF!+J3 -> #REF!
B4: - Электричество | C4: =#REF! -> #REF! | D4: =#REF! -> #REF! | E4: =#REF! -> #REF! | F4: =#REF! -> #REF! | G4: =#REF! -> #REF! | H4: =#REF! -> #REF! | J4: =#REF! -> #REF! | K4: =C4/#REF! -> #REF! | L4: =K4*#REF!+D4 -> #REF! | M4: =K4*#REF!+E4 -> #REF! | N4: =K4*#REF!+F4 -> #REF! | O4: =K4*#REF!+G4 -> #REF! | P4: =K4*#REF!+H4 -> #REF! | Q4: =K4*#REF!+J4 -> #REF!
B5: - Вода и отопление | C5: =#REF! -> #REF! | D5: =#REF! -> #REF! | E5: =#REF! -> #REF! | F5: =#REF! -> #REF! | G5: =#REF! -> #REF! | H5: =#REF! -> #REF! | J5: =#REF! -> #REF! | K5: =C5/#REF! -> #REF! | L5: =K5*#REF!+D5 -> #REF! | M5: =K5*#REF!+E5 -> #REF! | N5: =K5*#REF!+F5 -> #REF! | O5: =K5*#REF!+G5 -> #REF! | P5: =K5*#REF!+H5 -> #REF! | Q5: =K5*#REF!+J5 -> #REF!
B6: - Вывоз мусора | C6: =#REF! -> #REF! | D6: =#REF! -> #REF! | E6: =#REF! -> #REF! | F6: =#REF! -> #REF! | G6: =#REF! -> #REF! | H6: =#REF! -> #REF! | J6: =#REF! -> #REF! | K6: =C6/#REF! -> #REF! | L6: =K6*#REF!+D6 -> #REF! | M6: =K6*#REF!+E6 -> #REF! | N6: =K6*#REF!+F6 -> #REF! | O6: =K6*#REF!+G6 -> #REF! | P6: =K6*#REF!+H6 -> #REF! | Q6: =K6*#REF!+J6 -> #REF!
B7: - Техобслуж. помещ. | C7: =#REF! -> #REF! | D7: =#REF! -> #REF! | E7: =#REF! -> #REF! | F7: =#REF! -> #REF! | G7: =#REF! -> #REF! | H7: =#REF! -> #REF! | J7: =#REF! -> #REF! | K7: =C7/#REF! -> #REF! | L7: =K7*#REF!+D7 -> #REF! | M7: =K7*#REF!+E7 -> #REF! | N7: =K7*#REF!+F7 -> #REF! | O7: =K7*#REF!+G7 -> #REF! | P7: =K7*#REF!+H7 -> #REF! | Q7: =K7*#REF!+J7 -> #REF!
B8: - Клининговые услуги | C8: =#REF! -> #REF! | D8: =#REF!+SUM(СЧЕТА!E82:K82) -> #REF! | E8: =#REF!+SUM(СЧЕТА!L82:R82) -> #REF! | F8: =#REF!+SUM(СЧЕТА!S82:Y82) -> #REF! | G8: =#REF!+SUM(СЧЕТА!Z82:AF82) -> #REF! | H8: =#REF!+SUM(СЧЕТА!AG82:AM82) -> #REF! | I8: =#REF!+SUM(СЧЕТА!J82:P82) -> #REF! | J8: =#REF!+SUM(СЧЕТА!AN82:AT82) -> #REF! | K8: =C8/#REF! -> #REF! | L8: =K8*#REF!+D8 -> #REF! | M8: =K8*#REF!+E8 -> #REF! | N8: =K8*#REF!+F8 -> #REF! | O8: =K8*#REF!+G8 -> #REF! | P8: =K8*#REF!+H8 -> #REF! | Q8: =K8*#REF!+J8 -> #REF!
B9: Материалы | C9: =#REF! -> #REF! | D9: =#REF!+SUM(СЧЕТА!E71:K71) -> #REF! | E9: =#REF!+SUM(СЧЕТА!L71:R71) -> #REF! | F9: =#REF!+SUM(СЧЕТА!S71:Y71) -> #REF! | G9: =#REF!+SUM(СЧЕТА!Z71:AF71) -> #REF! | H9: =#REF!+SUM(СЧЕТА!AG71:AM71) -> #REF! | I9: =#REF!+SUM(СЧЕТА!J71:P71) -> #REF! | J9: =#REF!+SUM(СЧЕТА!AN71:AT71) -> #REF! | K9: =C9/#REF! -> #REF! | L9: =K9*#REF!+D9 -> #REF! | M9: =K9*#REF!+E9 -> #REF! | N9: =K9*#REF!+F9 -> #REF! | O9: =K9*#REF!+G9 -> #REF! | P9: =K9*#REF!+H9 -> #REF! | Q9: =K9*#REF!+J9 -> #REF!
B10: Услуги связи (телефонная мобильная связь) | C10: =#REF! -> #REF! | D10: =#REF!+SUM(СЧЕТА!E61:K61) -> #REF! | E10: =#REF!+SUM(СЧЕТА!L61:R61) -> #REF! | F10: =#REF!+SUM(СЧЕТА!S61:Y61) -> #REF! | G10: =#REF!+SUM(СЧЕТА!Z61:AF61) -> #REF! | H10: =#REF!+SUM(СЧЕТА!AG61:AM61) -> #REF! | I10: =#REF!+SUM(СЧЕТА!J72:P72) -> #REF! | J10: =#REF!+SUM(СЧЕТА!AN61:AT61) -> #REF! | K10: =C10/#REF! -> #REF! | L10: =K10*#REF!+D10 -> #REF! | M10: =K10*#REF!+E10 -> #REF! | N10: =K10*#REF!+F10 -> #REF! | O10: =K10*#REF!+G10 -> #REF! | P10: =K10*#REF!+H10 -> #REF! | Q10: =K10*#REF!+J10 -> #REF!
B11: Транспортно-экспедиционные расходы | C11: =#REF! -> #REF! | D11: =#REF!+SUM(СЧЕТА!E62:K62)+SUM(СЧЕТА!E63:K63) -> #REF! | E11: =#REF!+SUM(СЧЕТА!L62:R62)+SUM(СЧЕТА!L63:R63) -> #REF! | F11: =#REF!+SUM(СЧЕТА!S62:Y62)+SUM(СЧЕТА!S63:Y63) -> #REF! | G11: =#REF!+SUM(СЧЕТА!Z62:AF62)+SUM(СЧЕТА!Z63:AF63) -> #REF! | H11: =#REF!+SUM(СЧЕТА!AG62:AM62)+SUM(СЧЕТА!AG63:AM63) -> #REF! | I11: =#REF!+SUM(СЧЕТА!J62:P62)+SUM(СЧЕТА!J63:P63) -> #REF! | J11: =#REF!+SUM(СЧЕТА!AN62:AT62)+SUM(СЧЕТА!AN63:AT63) -> #REF! | K11: =C11/#REF! -> #REF! | L11: =K11*#REF!+D11 -> #REF! | M11: =K11*#REF!+E11 -> #REF! | N11: =K11*#REF!+F11 -> #REF! | O11: =K11*#REF!+G11 -> #REF! | P11: =K11*#REF!+H11 -> #REF! | Q11: =K11*#REF!+J11 -> #REF!
B12: Ремонт, техобслуживание | C12: =#REF! -> #REF! | D12: =#REF!+SUM(СЧЕТА!E77:K77) -> #REF! | E12: =#REF!+SUM(СЧЕТА!L77:R77) -> #REF! | F12: =#REF!+SUM(СЧЕТА!S77:Y77) -> #REF! | G12: =#REF!+SUM(СЧЕТА!Z77:AF77) -> #REF! | H12: =#REF!+SUM(СЧЕТА!AG77:AM77) -> #REF! | I12: =#REF!+SUM(СЧЕТА!J77:P77) -> #REF! | J12: =#REF!+SUM(СЧЕТА!AN77:AT77) -> #REF! | K12: =C12/#REF! -> #REF! | L12: =K12*#REF!+D12 -> #REF! | M12: =K12*#REF!+E12 -> #REF! | N12: =K12*#REF!+F12 -> #REF! | O12: =K12*#REF!+G12 -> #REF! | P12: =K12*#REF!+H12 -> #REF! | Q12: =K12*#REF!+J12 -> #REF!
B13: Командировочные расходы | C13: =#REF! -> #REF! | D13: =#REF!+SUM(СЧЕТА!E51:K51)+SUM(СЧЕТА!E68:K68)+SUM(СЧЕТА!E81:K81)+SUM(СЧЕТА!E57:K57) -> #REF! | E13: =#REF!+SUM(СЧЕТА!L51:R51)+SUM(СЧЕТА!L68:R68)+SUM(СЧЕТА!L81:R81)+SUM(СЧЕТА!L57:R57) -> #REF! | F13: =#REF!+SUM(СЧЕТА!S51:Y51)+SUM(СЧЕТА!S68:Y68)+SUM(СЧЕТА!S81:Y81)+SUM(СЧЕТА!S57:Y57) -> #REF! | G13: =#REF!+SUM(СЧЕТА!Z51:AF51)+SUM(СЧЕТА!Z68:AF68)+SUM(СЧЕТА!Z81:AF81)+SUM(СЧЕТА!Z57:AF57) -> #REF! | H13: =#REF!+SUM(СЧЕТА!AG51:AM51)+SUM(СЧЕТА!AG68:AM68)+SUM(СЧЕТА!AG81:AM81)+SUM(СЧЕТА!AG57:AM57) -> #REF! | I13: =#REF!+SUM(СЧЕТА!J51:P51)+SUM(СЧЕТА!J68:P68)+SUM(СЧЕТА!J81:P81) -> #REF! | J13: =#REF!+SUM(СЧЕТА!AN51:AT51)+SUM(СЧЕТА!AN68:AT68)+SUM(СЧЕТА!AN81:AT81)+SUM(СЧЕТА!AN57:AT57) -> #REF! | K13: =C13/#REF! -> #REF! | L13: =K13*#REF!+D13 -> #REF! | M13: =K13*#REF!+E13 -> #REF! | N13: =K13*#REF!+F13 -> #REF! | O13: =K13*#REF!+G13 -> #REF! | P13: =K13*#REF!+H13 -> #REF! | Q13: =K13*#REF!+J13 -> #REF!
B14: Охрана | C14: =#REF! -> #REF! | D14: =#REF!+SUM(СЧЕТА!E65:K65) -> #REF! | E14: =#REF!+SUM(СЧЕТА!L65:R65) -> #REF! | F14: =#REF!+SUM(СЧЕТА!S65:Y65) -> #REF! | G14: =#REF!+SUM(СЧЕТА!Z65:AF65) -> #REF! | H14: =#REF!+SUM(СЧЕТА!AG65:AM65) -> #REF! | I14: =#REF!+SUM(СЧЕТА!J65,СЧЕТА!P65) -> #REF! | J14: =#REF!+SUM(СЧЕТА!AN65:AT65) -> #REF! | K14: =C14/#REF! -> #REF! | L14: =K14*#REF!+D14 -> #REF! | M14: =K14*#REF!+E14 -> #REF! | N14: =K14*#REF!+F14 -> #REF! | O14: =K14*#REF!+G14 -> #REF! | P14: =K14*#REF!+H14 -> #REF! | Q14: =K14*#REF!+J14 -> #REF!
B15: Информационные технологии | C15: =#REF! -> #REF! | D15: =#REF!+SUM(СЧЕТА!E54:K54)+SUM(СЧЕТА!E59:K59)+SUM(СЧЕТА!E75:K75)+SUM(СЧЕТА!E76:K76) -> #REF! | E15: =#REF!+SUM(СЧЕТА!L54:R54)+SUM(СЧЕТА!L59:R59)+SUM(СЧЕТА!L75:R75)+SUM(СЧЕТА!L76:R76) -> #REF! | F15: =#REF!+SUM(СЧЕТА!S54:Y54)+SUM(СЧЕТА!S59:Y59)+SUM(СЧЕТА!S75:Y75)+SUM(СЧЕТА!S76:Y76) -> #REF! | G15: =#REF!+SUM(СЧЕТА!Z54:AF54)+SUM(СЧЕТА!Z59:AF59)+SUM(СЧЕТА!Z75:AF75)+SUM(СЧЕТА!Z76:AF76) -> #REF! | H15: =#REF!+SUM(СЧЕТА!AG54:AM54)+SUM(СЧЕТА!AG59:AM59)+SUM(СЧЕТА!AG75:AM75)+SUM(СЧЕТА!AG76:AM76) -> #REF! | I15: =#REF!+SUM(СЧЕТА!J54:P54)+SUM(СЧЕТА!J59:P59)+SUM(СЧЕТА!J75:P75)+SUM(СЧЕТА!J76:P76) -> #REF! | J15: =#REF!+SUM(СЧЕТА!AN54:AT54)+SUM(СЧЕТА!AN59:AT59)+SUM(СЧЕТА!AN75:AT75)+SUM(СЧЕТА!AN76:AT76) -> #REF! | K15: =C15/#REF! -> #REF! | L15: =K15*#REF!+D15 -> #REF! | M15: =K15*#REF!+E15 -> #REF! | N15: =K15*#REF!+F15 -> #REF! | O15: =K15*#REF!+G15 -> #REF! | P15: =K15*#REF!+H15 -> #REF! | Q15: =K15*#REF!+J15 -> #REF!
B16: Медкомиссия, санит., лабор. услуги, дезработы | C16: =#REF! -> #REF! | D16: =#REF!+SUM(СЧЕТА!E69:K69) -> #REF! | E16: =#REF!+SUM(СЧЕТА!L69:R69) -> #REF! | F16: =#REF!+SUM(СЧЕТА!S69:Y69) -> #REF! | G16: =#REF!+SUM(СЧЕТА!Z69:AF69) -> #REF! | H16: =#REF!+SUM(СЧЕТА!AG69:AM69) -> #REF! | I16: =#REF!+SUM(СЧЕТА!J69:P69) -> #REF! | J16: =#REF!+SUM(СЧЕТА!AN69:AT69) -> #REF! | K16: =C16/#REF! -> #REF! | L16: =K16*#REF!+D16 -> #REF! | M16: =K16*#REF!+E16 -> #REF! | N16: =K16*#REF!+F16 -> #REF! | O16: =K16*#REF!+G16 -> #REF! | P16: =K16*#REF!+H16 -> #REF! | Q16: =K16*#REF!+J16 -> #REF!
B17: Оплата квартиры | C17: =#REF! -> #REF! | D17: =#REF! -> #REF! | E17: =#REF! -> #REF! | F17: =#REF! -> #REF! | G17: =#REF! -> #REF! | H17: =#REF! -> #REF! | J17: =#REF! -> #REF! | K17: =C17/#REF! -> #REF! | L17: =K17*#REF!+D17 -> #REF! | M17: =K17*#REF!+E17 -> #REF! | N17: =K17*#REF!+F17 -> #REF! | O17: =K17*#REF!+G17 -> #REF! | P17: =K17*#REF!+H17 -> #REF! | Q17: =K17*#REF!+J17 -> #REF!
B18: Лицензионная музыка | C18: =#REF! -> #REF! | D18: =#REF!+SUM(СЧЕТА!E53:K53)+SUM(СЧЕТА!E58:K58)+SUM(СЧЕТА!E79:K79)+SUM(СЧЕТА!E80:K80)+SUM(СЧЕТА!E74:K74)+SUM(СЧЕТА!E66:K66)+SUM(СЧЕТА!E67:K67) -> #REF! | E18: =#REF!+SUM(СЧЕТА!R53:FL53)+SUM(СЧЕТА!L58:R58)+SUM(СЧЕТА!L79:R79)+SUM(СЧЕТА!L80:R80)+SUM(СЧЕТА!L74:R74)+SUM(СЧЕТА!L66:R66)+SUM(СЧЕТА!L67:R67) -> #REF! | F18: =#REF!+SUM(СЧЕТА!S53:Y53)+SUM(СЧЕТА!S58:Y58)+SUM(СЧЕТА!S79:Y79)+SUM(СЧЕТА!S80:Y80)+SUM(СЧЕТА!S74:Y74)+SUM(СЧЕТА!S66:Y66)+SUM(СЧЕТА!S67:Y67) -> #REF! | G18: =#REF!+SUM(СЧЕТА!Z53:AF53)+SUM(СЧЕТА!Z58:AF58)+SUM(СЧЕТА!Z79:AF79)+SUM(СЧЕТА!Z80:AF80)+SUM(СЧЕТА!Z74:AF74)+SUM(СЧЕТА!Z66:AF66)+SUM(СЧЕТА!Z67:AF67) -> #REF! | H18: =#REF!+SUM(СЧЕТА!AG53:AM53)+SUM(СЧЕТА!AG58:AM58)+SUM(СЧЕТА!AG79:AM79)+SUM(СЧЕТА!AG80:AM80)+SUM(СЧЕТА!AG74:AM74)+SUM(СЧЕТА!AG66:AM66)+SUM(СЧЕТА!AG67:AM67) -> #REF! | I18: =#REF!+SUM(СЧЕТА!J53:P53)+SUM(СЧЕТА!J58:P58)+SUM(СЧЕТА!J79:P79)+SUM(СЧЕТА!J80:P80)+SUM(СЧЕТА!J74:P74)+SUM(СЧЕТА!J66:P66) -> #REF! | J18: =#REF!+SUM(СЧЕТА!AN53:AT53)+SUM(СЧЕТА!AN58:AT58)+SUM(СЧЕТА!AN79:AT79)+SUM(СЧЕТА!AN80:AT80)+SUM(СЧЕТА!AM74:AT74)+SUM(СЧЕТА!AM66:AT66)+SUM(СЧЕТА!AN67:AT67) -> #REF! | K18: =C18/#REF! -> #REF! | L18: =K18*#REF!+D18 -> #REF! | M18: =K18*#REF!+E18 -> #REF! | N18: =K18*#REF!+F18 -> #REF! | O18: =K18*#REF!+G18 -> #REF! | P18: =K18*#REF!+H18 -> #REF! | Q18: =K18*#REF!+J18 -> #REF!
B19: Оценка соблюдения стандартов | C19: =#REF! -> #REF! | D19: =#REF!+ SUM(СЧЕТА!E73:'СЧЕТА'!K73) -> #REF! | E19: =#REF!+ SUM(СЧЕТА!L73:'СЧЕТА'!R73) -> #REF! | F19: =#REF!+ SUM(СЧЕТА!S73:'СЧЕТА'!Y73) -> #REF! | G19: =#REF!+ SUM(СЧЕТА!Z73:'СЧЕТА'!AF73) -> #REF! | H19: =#REF!+ SUM(СЧЕТА!AG73:'СЧЕТА'!AM73) -> #REF! | I19: =#REF!+ SUM(СЧЕТА!J73:'СЧЕТА'!P73) -> #REF! | J19: =#REF!+ SUM(СЧЕТА!AN73:'СЧЕТА'!AT73) -> #REF! | K19: =C19/#REF! -> #REF! | L19: =K19*#REF!+D19 -> #REF! | M19: =K19*#REF!+E19 -> #REF! | N19: =K19*#REF!+F19 -> #REF! | O19: =K19*#REF!+G19 -> #REF! | P19: =K19*#REF!+H19 -> #REF! | Q19: =K19*#REF!+J19 -> #REF!
B20: Прочие операционные расходы | C20: =#REF! -> #REF! | D20: =#REF!+SUM(СЧЕТА!E70:K70)+SUM(СЧЕТА!E72:'СЧЕТА'!K72) -> #REF! | E20: =#REF!+SUM(СЧЕТА!L70:R70)+SUM(СЧЕТА!L72:'СЧЕТА'!R72) -> #REF! | F20: =#REF!+SUM(СЧЕТА!S70:Y70)+SUM(СЧЕТА!S72:'СЧЕТА'!Y72) -> #REF! | G20: =#REF!+SUM(СЧЕТА!Z70:AF70)+SUM(СЧЕТА!Z72:'СЧЕТА'!AF72) -> #REF! | H20: =#REF!+SUM(СЧЕТА!AG70:AM70)+SUM(СЧЕТА!AG72:'СЧЕТА'!AM72) -> #REF! | I20: =#REF!+SUM(СЧЕТА!J70:P70)+SUM(СЧЕТА!J72:'СЧЕТА'!P72) -> #REF! | J20: =#REF!+SUM(СЧЕТА!AN70:AT70)+SUM(СЧЕТА!AN72:'СЧЕТА'!AT72) -> #REF! | K20: =C20/#REF! -> #REF! | L20: =K20*#REF!+D20 -> #REF! | M20: =K20*#REF!+E20 -> #REF! | N20: =K20*#REF!+F20 -> #REF! | O20: =K20*#REF!+G20 -> #REF! | P20: =K20*#REF!+H20 -> #REF! | Q20: =K20*#REF!+J20 -> #REF!
I34: =C34:C46 -> 0
I68: 40

Sheet Semis
A1: Ресторан: | U1: Версия: 01.17 | AB1: План | AC1: ПРОШ. ГОД | AD1: Факт
A2: Месяц: | X2: 1 | Y2: Алмаз | Z2: 42736 | AB2: =P11 -> 530000 | AC2: 4133000 | AF2: =AB3/AB2 -> #REF! | AG2: =AC3/AC2 -> 0.23440455 | AH2: =AD3/AB8 -> #DIV/0!
A3: Всего дней в месяце: | C3: 30 | U3: Вносим данные только в белые ячейки | X3: 2 | Y3: Армада Север | Z3: 42767 | AB3: =P25+#REF!+P47+#REF!+#REF! -> #REF! | AC3: 968794 | AF3: =AB2/P17 -> #DIV/0! | AH3: =R14 -> 0
X4: 3 | Y4: Ашкадар | Z4: 42795
X5: 4 | Y5: Восход | Z5: 42826 | AB5: =DATE(YEAR(C2),MONTH(C2)+1,0) -> 31
X6: 5 | Y6: Галант | Z6: 42856
X7: 6 | Y7: Галле | Z7: 42887 | AB7: =WEEKDAY(C2,2) -> 6
A8: Неделя | D8: =1+INT((C2-(DATE(YEAR(C2),1,2)-WEEKDAY(DATE(YEAR(C2),1,0))))/7) -> 1 | F8: =D8+1 -> 2 | H8: =F8+1 -> 3 | J8: =H8+1 -> 4 | L8: =J8+1 -> 5 | N8: =L8+1 -> 6 | P8: План | R8: Факт | T8: Разница | U8: Комментарии | X8: 7 | Y8: Горки | Z8: 42917 | AB8: =R11 -> 0
A9: Дней в неделе | D9: 7 | F9: 7 | H9: 7 | J9: 7 | L9: 3 | X9: 8 | Y9: Гостиный Двор | Z9: 42948
A10: Статья расхода | D10: План | E10: Факт | F10: План | G10: Факт | H10: План | I10: Факт | J10: План | K10: Факт | L10: План | M10: Факт | N10: План | O10: Факт | P10: Руб | Q10: % | R10: Руб | S10: % | X10: 9 | Y10: Гулливер | Z10: 42979
A11: SALES | N11: 530000 | P11: =SUM(F11+H11+J11+L11+N11+D11) -> 530000 | R11: =E11+G11+I11+K11+M11+O11 -> 0 | T11: =R11-P11 -> -530000 | X11: 10 | Y11: Дёма | Z11: 43009
W14: =SUM(P15:Q16) -> 0 | X14: 11 | Y14: Континент | Z14: 43040
X15: 12 | Y15: Космонавтов | Z15: 43070
X16: 13 | Y16: МЕГА
X17: 14 | Y17: Меркурий
X18: 15 | Y18: Ниагара
A19: Природный газ | D19: =($P19/$C$3)*$D$9 -> 0 | F19: =($P19/$C$3)*F$9 -> 0 | H19: =($P19/$C$3)*H$9 -> 0 | J19: =($P19/$C$3)*J$9 -> 0 | L19: =($P19/$C$3)*L$9 -> 0 | N19: =($P19/$C$3)*N$9 -> 0 | Q19: =P19/$AB$2 -> 0 | R19: =SUM(E19+G19+I19+K19+M19+O19) -> 0 | S19: =R19/R11 -> #DIV/0! | T19: =P19-R19 -> 0 | X19: 16 | Y19: Планета
A20: Электричество | D20: =($P20/$C$3)*$D$9 -> 0 | F20: =($P20/$C$3)*F$9 -> 0 | H20: =($P20/$C$3)*H$9 -> 0 | J20: =($P20/$C$3)*J$9 -> 0 | L20: =($P20/$C$3)*L$9 -> 0 | N20: =($P20/$C$3)*N$9 -> 0 | Q20: =P20/$AB$2 -> 0 | R20: =SUM(E20+G20+I20+K20+M20+O20) -> 0 | S20: =R20/R11 -> #DIV/0! | T20: =P20-R20 -> 0 | X20: 17 | Y20: Простор
A21: Вода и отопление | D21: =($P21/$C$3)*$D$9 -> 0 | F21: =($P21/$C$3)*F$9 -> 0 | H21: =($P21/$C$3)*H$9 -> 0 | J21: =($P21/$C$3)*J$9 -> 0 | L21: =($P21/$C$3)*L$9 -> 0 | N21: =($P21/$C$3)*N$9 -> 0 | Q21: =P21/$AB$2 -> 0 | R21: =SUM(E21+G21+I21+K21+M21+O21) -> 0 | S21: =R21/R11 -> #DIV/0! | T21: =P21-R21 -> 0 | X21: 19 | Y21: Сипайлово
A22: Вывоз мусора | D22: =($P22/$C$3)*$D$9 -> 0 | F22: =($P22/$C$3)*F$9 -> 0 | H22: =($P22/$C$3)*H$9 -> 0 | J22: =($P22/$C$3)*J$9 -> 0 | L22: =($P22/$C$3)*L$9 -> 0 | N22: =($P22/$C$3)*N$9 -> 0 | Q22: =P22/$AB$2 -> 0 | R22: =SUM(E22+G22+I22+K22+M22+O22) -> 0 | S22: =R22/R11 -> #DIV/0! | T22: =P22-R22 -> 0 | X22: 18 | Y22: Семья
A23: Техобслуживание помещения | D23: =($P23/$C$3)*$D$9 -> 0 | F23: =($P23/$C$3)*F$9 -> 0 | H23: =($P23/$C$3)*H$9 -> 0 | J23: =($P23/$C$3)*J$9 -> 0 | L23: =($P23/$C$3)*L$9 -> 0 | N23: =($P23/$C$3)*N$9 -> 0 | Q23: =P23/$AB$2 -> 0 | R23: =E23+G23+I23+K23+M23+O23 -> 0 | S23: =R23/R11 -> #DIV/0! | T23: =P23-R23 -> 0 | X23: 21 | Y23: Флагман
A24: Клининговые услуги | D24: =($P24/$C$3)*$D$9 -> 0 | F24: =($P24/$C$3)*F$9 -> 0 | H24: =($P24/$C$3)*H$9 -> 0 | J24: =($P24/$C$3)*J$9 -> 0 | L24: =($P24/$C$3)*L$9 -> 0 | N24: =($P24/$C$3)*N$9 -> 0 | Q24: =P24/$AB$2 -> 0 | R24: =E24+G24+I24+K24+M24+O24 -> 0 | S24: =R24/R11 -> #DIV/0! | T24: =P24-R24 -> 0 | X24: 22
A25: Коммунальные услуги | D25: =SUM(D19:D24) -> 0 | E25: =SUM(E19:E24) -> 0 | F25: =SUM(F19:F24) -> 0 | G25: =SUM(G19:G24) -> 0 | H25: =SUM(H19:H24) -> 0 | I25: =SUM(I19:I24) -> 0 | J25: =SUM(J19:J24) -> 0 | K25: =SUM(K19:K24) -> 0 | ... P25: =SUM(P19:P24) -> 0 | Q25: =P25/$AB$2 -> 0 | R25: =SUM(R19:R24) -> 0 | S25: =SUM(S19:S24) -> #DIV/0! | T25: =P25-R25 -> 0 | X25: 25
A26: МБП | D26: =P26/C3*D9 -> 0 | F26: =P26/C3*F9 -> 0 | H26: =P26/C3*H9 -> 0 | J26: =P26/C3*J9 -> 0 | L26: =P26/C3*L9 -> 0 | N26: =P26/C3*N9 -> 0 | Q26: =P26/$AB$2 -> 0 | R26: =E26+G26+I26+K26+M26+O26 -> 0 | S26: =R26/R11 -> #DIV/0! | T26: =P26-R26 -> 0 | X26: 26
A27: Канцтовары | D27: =P27/C3*D9 -> 0 | F27: =P27/C3*F9 -> 0 | H27: =P27/C3*H9 -> 0 | J27: =P27/C3*J9 -> 0 | L27: =P27/C3*L9 -> 0 | N27: =P27/C3*N9 -> 0 | Q27: =P27/$AB$2 -> 0 | R27: =E27+G27+I27+K27+M27+O27 -> 0 | S27: =R27/R11 -> #DIV/0! | T27: =P27-R27 -> 0
A28: Униформа | D28: =P28/C3*D9 -> 0 | F28: =P28/C3*F9 -> 0 | H28: =P28/C3*H9 -> 0 | J28: =P28/C3*J9 -> 0 | L28: =P28/C3*L9 -> 0 | N28: =P28/C3*N9 -> 0 | Q28: =P28/$AB$2 -> 0 | R28: =E28+G28+I28+K28+M28+O28 -> 0 | S28: =R28/R11 -> #DIV/0! | T28: =P28-R28 -> 0
A29: Чистящие средства | D29: =P29/C3*D9 -> 0 | F29: =P29/C3*F9 -> 0 | H29: =P29/C3*H9 -> 0 | J29: =P29/C3*J9 -> 0 | L29: =P29/C3*L9 -> 0 | N29: =P29/C3*N9 -> 0 | Q29: =P29/$AB$2 -> 0 | R29: =E29+G29+I29+K29+M29+O29 -> 0 | S29: =R29/R11 -> #DIV/0! | T29: =P29-R29 -> 0
A30: Сервис | D30: =P30/C3*D9 -> 0 | F30: =P30/C3*F9 -> 0 | H30: =P30/C3*H9 -> 0 | J30: =P30/C3*J9 -> 0 | L30: =P30/C3*L9 -> 0 | N30: =P30/C3*N9 -> 0 | Q30: =P30/$AB$2 -> 0 | R30: =E30+G30+I30+K30+M30+O30 -> 0 | S30: =R30/R11 -> #DIV/0! | T30: =P30-R30 -> 0
A31: Прочие | D31: =P31/C3*D9 -> 0 | F31: =P31/C3*F9 -> 0 | H31: =P31/C3*H9 -> 0 | J31: =P31/C3*J9 -> 0 | L31: =P31/C3*L9 -> 0 | N31: =P31/C3*N9 -> 0 | Q31: =P31/$AB$2 -> 0 | R31: =E31+G31+I31+K31+M31+O31 -> 0 | S31: =R31/R11 -> #DIV/0! | T31: =P31-R31 -> 0 | X31: 27
A32: Материалы | D32: =SUM(D26:D31) -> 0 | E32: =SUM(E26:E31) -> 0 | F32: =SUM(F26:F31) -> 0 | G32: =SUM(G26:G31) -> 0 | H32: =SUM(H26:H31) -> 0 | I32: =SUM(I26:I31) -> 0 | J32: =SUM(J26:J31) -> 0 | K32: =SUM(K26:K31) -> 0 | ... P32: =SUM(P26:P31) -> 0 | Q32: =P32/$AB$2 -> 0 | R32: =SUM(R26:R31) -> 0 | S32: =SUM(S26:S31) -> #DIV/0! | T32: =P32-R32 -> 0 | X32: 29
A33: Услуги связи (телефонная, мобильная связь) | D33: =($P33/$C$3)*$D$9 -> 0 | F33: =($P33/$C$3)*F$9 -> 0 | H33: =($P33/$C$3)*H$9 -> 0 | J33: =($P33/$C$3)*J$9 -> 0 | L33: =($P33/$C$3)*L$9 -> 0 | N33: =($P33/$C$3)*N$9 -> 0 | Q33: =P33/$AB$2 -> 0 | R33: =SUM(E33+G33+I33+K33+M33+O33) -> 0 | S33: =R33/R11 -> #DIV/0! | T33: =P33-R33 -> 0 | X33: 30
A34: Оплата квартиры | D34: =($P34/$C$3)*$D$9 -> 0 | F34: =($P34/$C$3)*F$9 -> 0 | H34: =($P34/$C$3)*H$9 -> 0 | J34: =($P34/$C$3)*J$9 -> 0 | L34: =($P34/$C$3)*L$9 -> 0 | N34: =($P34/$C$3)*N$9 -> 0 | Q34: =P34/$AB$2 -> 0 | R34: =SUM(E34+G34+I34+K34+M34+O34) -> 0 | S34: =R34/R11 -> #DIV/0! | T34: =P34-R34 -> 0
A35: Транспортно-экспедиционные расходы | D35: =($P35/$C$3)*$D$9 -> 0 | F35: =($P35/$C$3)*F$9 -> 0 | H35: =($P35/$C$3)*H$9 -> 0 | J35: =($P35/$C$3)*J$9 -> 0 | L35: =($P35/$C$3)*L$9 -> 0 | N35: =($P35/$C$3)*N$9 -> 0 | Q35: =P35/$AB$2 -> 0 | R35: =SUM(E35+G35+I35+K35+M35+O35) -> 0 | S35: =R35/R11 -> #DIV/0! | T35: =P35-R35 -> 0
A36: Информационные технологии | D36: =($P36/$C$3)*$D$9 -> 0 | F36: =($P36/$C$3)*F$9 -> 0 | H36: =($P36/$C$3)*H$9 -> 0 | J36: =($P36/$C$3)*J$9 -> 0 | L36: =($P36/$C$3)*L$9 -> 0 | N36: =($P36/$C$3)*N$9 -> 0 | Q36: =P36/$AB$2 -> 0 | R36: =SUM(E36+G36+I36+K36+M36+O36) -> 0 | S36: =R36/R11 -> #DIV/0! | T36: =P36-R36 -> 0
A37: Охранные услуги | D37: =($P37/$C$3)*$D$9 -> 0 | F37: =($P37/$C$3)*F$9 -> 0 | H37: =($P37/$C$3)*H$9 -> 0 | J37: =($P37/$C$3)*J$9 -> 0 | L37: =($P37/$C$3)*L$9 -> 0 | N37: =($P37/$C$3)*N$9 -> 0 | Q37: =P37/$AB$2 -> 0 | R37: =SUM(E37+G37+I37+K37+M37+O37) -> 0 | S37: =R37/R11 -> #DIV/0! | T37: =P37-R37 -> 0
A38: Командировочные расходы | D38: =($P38/$C$3)*$D$9 -> 0 | F38: =($P38/$C$3)*F$9 -> 0 | H38: =($P38/$C$3)*H$9 -> 0 | J38: =($P38/$C$3)*J$9 -> 0 | L38: =($P38/$C$3)*L$9 -> 0 | N38: =($P38/$C$3)*N$9 -> 0 | Q38: =P38/$AB$2 -> 0 | R38: =SUM(E38+G38+I38+K38+M38+O38) -> 0 | S38: =R38/R11 -> #DIV/0! | T38: =P38-R38 -> 0
A39: Оценка и соблюдение стандартов | D39: =($P39/$C$3)*$D$9 -> 0 | F39: =($P39/$C$3)*F$9 -> 0 | H39: =($P39/$C$3)*H$9 -> 0 | J39: =($P39/$C$3)*J$9 -> 0 | L39: =($P39/$C$3)*L$9 -> 0 | N39: =($P39/$C$3)*N$9 -> 0 | Q39: =P39/$AB$2 -> 0 | R39: =SUM(E39+G39+I39+K39+M39+O39) -> 0 | S39: =R39/R11 -> #DIV/0! | T39: =P39-R39 -> 0
A40: Лицензионная музыка | D40: =($P40/$C$3)*$D$9 -> 0 | F40: =($P40/$C$3)*F$9 -> 0 | H40: =($P40/$C$3)*H$9 -> 0 | J40: =($P40/$C$3)*J$9 -> 0 | L40: =($P40/$C$3)*L$9 -> 0 | N40: =($P40/$C$3)*N$9 -> 0 | Q40: =P40/$AB$2 -> 0 | R40: =SUM(E40+G40+I40+K40+M40+O40) -> 0 | S40: =R40/R11 -> #DIV/0! | T40: =P40-R40 -> 0
A41: Пени и штрафы | D41: =($P41/$C$3)*$D$9 -> 0 | F41: =($P41/$C$3)*F$9 -> 0 | H41: =($P41/$C$3)*H$9 -> 0 | J41: =($P41/$C$3)*J$9 -> 0 | L41: =($P41/$C$3)*L$9 -> 0 | N41: =($P41/$C$3)*N$9 -> 0 | Q41: =P41/$AB$2 -> 0 | R41: =SUM(E41+G41+I41+K41+M41+O41) -> 0 | S41: =R41/R11 -> #DIV/0! | T41: =P41-R41 -> 0
A42: Консультац.информационные услуги | D42: =($P42/$C$3)*$D$9 -> 0 | F42: =($P42/$C$3)*F$9 -> 0 | H42: =($P42/$C$3)*H$9 -> 0 | J42: =($P42/$C$3)*J$9 -> 0 | L42: =($P42/$C$3)*L$9 -> 0 | N42: =($P42/$C$3)*N$9 -> 0 | Q42: =P42/$AB$2 -> 0 | R42: =E42+G42+I42+K42+M42+O42 -> 0 | S42: =R42/R11 -> #DIV/0! | T42: =P42-R42 -> 0
...

Sheet Итог Год
A3: Статья бюджетов / Аналитика | C3: ЯНВАРЬ | E3: ФЕВРАЛЬ | G3: МАРТ | I3: Q1 | K3: АПРЕЛЬ | M3: МАЙ | O3: ИЮНЬ | Q3: Q2 | S3: ИЮЛЬ | U3: АВГУСТ | W3: СЕНТЯБРЬ | Y3: Q3 | AA3: ОКТЯБРЬ | AC3: НОЯБРЬ | AE3: ДЕКАБРЬ | AG3: Q4
C5: Сумма | D5: % | E5: Сумма | F5: % | G5: Сумма | H5: % | I5: Сумма | J5: % | K5: Сумма | L5: % | M5: Сумма | N5: % | O5: Сумма | P5: % | Q5: Сумма | R5: % | S5: Сумма | T5: % | U5: Сумма | V5: % | W5: Сумма | X5: % | Y5: Сумма | Z5: % | AA5: Сумма | AB5: % | AC5: Сумма | AD5: % | AE5: Сумма | AF5: % | AG5: Сумма | AH5: %
A6: Доходы | C6: =C7 -> 0 | D6: 100 | E6: =E7 -> 0 | F6: 100 | G6: =G7 -> 0 | H6: 100 | I6: =C6+E6+G6 -> 0 | J6: 100 | K6: =K7 -> 0 | L6: 100 | M6: =M7 -> 0 | N6: 100 | O6: =O7 -> 0 | P6: 100 | Q6: =K6+M6+O6 -> 0 | R6: 100 | S6: =S7 -> 0 | T6: 100 | U6: =U7 -> 0 | V6: 100 | W6: =W7 -> 0 | X6: 100 | Y6: =S6+U6+W6 -> 0 | Z6: 100 | AA6: =AA7 -> 0 | AB6: 100 | AC6: =AC7 -> 0 | AD6: 100 | AE6: =AE7 -> 0 | AF6: 100 | AG6: =AA6+AC6+AE6 -> 0 | AH6: 100
A7: SALES | C7: =SUM(C8:C8) -> 0 | D7: 100 | E7: =SUM(E8:E8) -> 0 | F7: 100 | G7: =SUM(G8:G8) -> 0 | H7: 100 | I7: =C7+E7+G7 -> 0 | J7: 100 | K7: =SUM(K8:K8) -> 0 | L7: 100 | M7: =SUM(M8:M8) -> 0 | N7: 100 | O7: =SUM(O8:O8) -> 0 | P7: 100 | Q7: =K7+M7+O7 -> 0 | R7: 100 | S7: =SUM(S8:S8) -> 0 | T7: 100 | U7: =SUM(U8:U8) -> 0 | V7: 100 | W7: =SUM(W8:W8) -> 0 | X7: 100 | Y7: =S7+U7+W7 -> 0 | Z7: 100 | AA7: =SUM(AA8:AA8) -> 0 | AB7: 100 | AC7: =SUM(AC8:AC8) -> 0 | AD7: 100 | AE7: =SUM(AE8:AE8) -> 0 | AF7: 100 | AG7: =AA7+AC7+AE7 -> 0 | AH7: 100
A8: Выручка (наличные) | D8: =C8/C$7*100 -> #DIV/0! | F8: =E8/E$7*100 -> #DIV/0! | H8: =G8/G$7*100 -> #DIV/0! | I8: =C8+E8+G8 -> 0 | J8: =I8/I$7*100 -> #DIV/0! | L8: =K8/K$7*100 -> #DIV/0! | N8: =M8/M$7*100 -> #DIV/0! | P8: =O8/O$7*100 -> #DIV/0! | Q8: =K8+M8+O8 -> 0 | R8: =Q8/Q$7*100 -> #DIV/0! | T8: =S8/S$7*100 -> #DIV/0! | V8: =U8/U$7*100 -> #DIV/0! | X8: =W8/W$7*100 -> #DIV/0! | Y8: =S8+U8+W8 -> 0 | Z8: =Y8/Y$7*100 -> #DIV/0! | AB8: =AA8/AA$7*100 -> #DIV/0! | AD8: =AC8/AC$7*100 -> #DIV/0! | AF8: =AE8/AE$7*100 -> #DIV/0! | AG8: =AA8+AC8+AE8 -> 0 | AH8: =AG8/AG$7*100 -> #DIV/0!
A9: SEMIS (Полуварьируемые затраты) | C9: =C10+C17+C24 -> 0 | D9: =C9/C$7*100 -> #DIV/0! | E9: =E10+E17+E24 -> 0 | F9: =E9/E$7*100 -> #DIV/0! | G9: =G10+G17+G24 -> 0 | H9: =G9/G$7*100 -> #DIV/0! | I9: =C9+E9+G9 -> 0 | J9: =I9/I$7*100 -> #DIV/0! | K9: =K10+K17+K24 -> 0 | L9: =K9/K$7*100 -> #DIV/0! | M9: =M10+M17+M24 -> 0 | N9: =M9/M$7*100 -> #DIV/0! | O9: =O10+O17+O24 -> 0 | P9: =O9/O$7*100 -> #DIV/0! | Q9: =K9+M9+O9 -> 0 | R9: =Q9/Q$7*100 -> #DIV/0! | S9: =S10+S17+S24+S48+S51+S55 -> 0 | T9: =S9/S$7*100 -> #DIV/0! | U9: =U10+U17+U24+U48+U51+U55 -> 0 | V9: =U9/U$7*100 -> #DIV/0! | W9: =W10+W17+W24+W48+W51+W55 -> 0 | X9: =W9/W$7*100 -> #DIV/0! | Y9: =S9+U9+W9 -> 0 | Z9: =Y9/Y$7*100 -> #DIV/0! | AA9: =AA10+AA17+AA24 -> 0 | AB9: =AA9/AA$7*100 -> #DIV/0! | AC9: =AC10+AC17+AC24 -> 0 | AD9: =AC9/AC$7*100 -> #DIV/0! | AE9: =AE10+AE17+AE24 -> 0 | AF9: =AE9/AE$7*100 -> #DIV/0! | AG9: =AA9+AC9+AE9 -> 0 | AH9: =AG9/AG$7*100 -> #DIV/0!
A10: Коммунальные услуги | C10: =SUM(C11:C16) -> 0 | D10: =C10/C$7*100 -> #DIV/0! | E10: =SUM(E11:E16) -> 0 | F10: =E10/E$7*100 -> #DIV/0! | G10: =SUM(G11:G16) -> 0 | H10: =G10/G$7*100 -> #DIV/0! | I10: =C10+E10+G10 -> 0 | J10: =I10/I$7*100 -> #DIV/0! | K10: =SUM(K11:K16) -> 0 | L10: =K10/K$7*100 -> #DIV/0! | M10: =SUM(M11:M16) -> 0 | N10: =M10/M$7*100 -> #DIV/0! | O10: =SUM(O11:O16) -> 0 | P10: =O10/O$7*100 -> #DIV/0! | Q10: =K10+M10+O10 -> 0 | R10: =Q10/Q$7*100 -> #DIV/0! | S10: =SUM(S11:S16) -> 0 | T10: =S10/S$7*100 -> #DIV/0! | U10: =SUM(U11:U16) -> 0 | V10: =U10/U$7*100 -> #DIV/0! | W10: =SUM(W11:W16) -> 0 | X10: =W10/W$7*100 -> #DIV/0! | Y10: =S10+U10+W10 -> 0 | Z10: =Y10/Y$7*100 -> #DIV/0! | AA10: =SUM(AA11:AA16) -> 0 | AB10: =AA10/AA$7*100 -> #DIV/0! | AC10: =SUM(AC11:AC16) -> 0 | AD10: =AC10/AC$7*100 -> #DIV/0! | AE10: =SUM(AE11:AE16) -> 0 | AF10: =AE10/AE$7*100 -> #DIV/0! | AG10: =AA10+AC10+AE10 -> 0 | AH10: =AG10/AG$7*100 -> #DIV/0!
A11: Коммун: природный газ | D11: =C11/C$7*100 -> #DIV/0! | F11: =E11/E$7*100 -> #DIV/0! | H11: =G11/G$7*100 -> #DIV/0! | I11: =C11+E11+G11 -> 0 | J11: =I11/I$7*100 -> #DIV/0! | L11: =K11/K$7*100 -> #DIV/0! | N11: =M11/M$7*100 -> #DIV/0! | P11: =O11/O$7*100 -> #DIV/0! | Q11: =K11+M11+O11 -> 0 | R11: =Q11/Q$7*100 -> #DIV/0! | T11: =S11/S$7*100 -> #DIV/0! | V11: =U11/U$7*100 -> #DIV/0! | X11: =W11/W$7*100 -> #DIV/0! | Y11: =S11+U11+W11 -> 0 | Z11: =Y11/Y$7*100 -> #DIV/0! | AB11: =AA11/AA$7*100 -> #DIV/0! | AD11: =AC11/AC$7*100 -> #DIV/0! | AF11: =AE11/AE$7*100 -> #DIV/0! | AG11: =AA11+AC11+AE11 -> 0 | AH11: =AG11/AG$7*100 -> #DIV/0!
A12: Коммун: электроэнергия | D12: =C12/C$7*100 -> #DIV/0! | F12: =E12/E$7*100 -> #DIV/0! | H12: =G12/G$7*100 -> #DIV/0! | I12: =C12+E12+G12 -> 0 | J12: =I12/I$7*100 -> #DIV/0! | L12: =K12/K$7*100 -> #DIV/0! | N12: =M12/M$7*100 -> #DIV/0! | P12: =O12/O$7*100 -> #DIV/0! | Q12: =K12+M12+O12 -> 0 | R12: =Q12/Q$7*100 -> #DIV/0! | T12: =S12/S$7*100 -> #DIV/0! | V12: =U12/U$7*100 -> #DIV/0! | X12: =W12/W$7*100 -> #DIV/0! | Y12: =S12+U12+W12 -> 0 | Z12: =Y12/Y$7*100 -> #DIV/0! | AB12: =AA12/AA$7*100 -> #DIV/0! | AD12: =AC12/AC$7*100 -> #DIV/0! | AF12: =AE12/AE$7*100 -> #DIV/0! | AG12: =AA12+AC12+AE12 -> 0 | AH12: =AG12/AG$7*100 -> #DIV/0!
A13: Коммун: водоснабжение и отопление | D13: =C13/C$7*100 -> #DIV/0! | F13: =E13/E$7*100 -> #DIV/0! | H13: =G13/G$7*100 -> #DIV/0! | I13: =C13+E13+G13 -> 0 | J13: =I13/I$7*100 -> #DIV/0! | L13: =K13/K$7*100 -> #DIV/0! | N13: =M13/M$7*100 -> #DIV/0! | P13: =O13/O$7*100 -> #DIV/0! | Q13: =K13+M13+O13 -> 0 | R13: =Q13/Q$7*100 -> #DIV/0! | T13: =S13/S$7*100 -> #DIV/0! | V13: =U13/U$7*100 -> #DIV/0! | X13: =W13/W$7*100 -> #DIV/0! | Y13: =S13+U13+W13 -> 0 | Z13: =Y13/Y$7*100 -> #DIV/0! | AB13: =AA13/AA$7*100 -> #DIV/0! | AD13: =AC13/AC$7*100 -> #DIV/0! | AF13: =AE13/AE$7*100 -> #DIV/0! | AG13: =AA13+AC13+AE13 -> 0 | AH13: =AG13/AG$7*100 -> #DIV/0!
A14: Коммун: вывоз мусора, очистка территории | D14: =C14/C$7*100 -> #DIV/0! | F14: =E14/E$7*100 -> #DIV/0! | H14: =G14/G$7*100 -> #DIV/0! | I14: =C14+E14+G14 -> 0 | J14: =I14/I$7*100 -> #DIV/0! | L14: =K14/K$7*100 -> #DIV/0! | N14: =M14/M$7*100 -> #DIV/0! | P14: =O14/O$7*100 -> #DIV/0! | Q14: =K14+M14+O14 -> 0 | R14: =Q14/Q$7*100 -> #DIV/0! | T14: =S14/S$7*100 -> #DIV/0! | V14: =U14/U$7*100 -> #DIV/0! | X14: =W14/W$7*100 -> #DIV/0! | Y14: =S14+U14+W14 -> 0 | Z14: =Y14/Y$7*100 -> #DIV/0! | AB14: =AA14/AA$7*100 -> #DIV/0! | AD14: =AC14/AC$7*100 -> #DIV/0! | AF14: =AE14/AE$7*100 -> #DIV/0! | AG14: =AA14+AC14+AE14 -> 0 | AH14: =AG14/AG$7*100 -> #DIV/0!
A15: Коммун: техобслуж.помещения | D15: =C15/C$7*100 -> #DIV/0! | F15: =E15/E$7*100 -> #DIV/0! | H15: =G15/G$7*100 -> #DIV/0! | I15: =C15+E15+G15 -> 0 | J15: =I15/I$7*100 -> #DIV/0! | L15: =K15/K$7*100 -> #DIV/0! | N15: =M15/M$7*100 -> #DIV/0! | P15: =O15/O$7*100 -> #DIV/0! | Q15: =K15+M15+O15 -> 0 | R15: =Q15/Q$7*100 -> #DIV/0! | T15: =S15/S$7*100 -> #DIV/0! | V15: =U15/U$7*100 -> #DIV/0! | X15: =W15/W$7*100 -> #DIV/0! | Y15: =S15+U15+W15 -> 0 | Z15: =Y15/Y$7*100 -> #DIV/0! | AB15: =AA15/AA$7*100 -> #DIV/0! | AD15: =AC15/AC$7*100 -> #DIV/0! | AF15: =AE15/AE$7*100 -> #DIV/0! | AG15: =AA15+AC15+AE15 -> 0 | AH15: =AG15/AG$7*100 -> #DIV/0!
A16: Коммун: клининговые услуги | D16: =C16/C$7*100 -> #DIV/0! | F16: =E16/E$7*100 -> #DIV/0! | H16: =G16/G$7*100 -> #DIV/0! | I16: =C16+E16+G16 -> 0 | J16: =I16/I$7*100 -> #DIV/0! | L16: =K16/K$7*100 -> #DIV/0! | N16: =M16/M$7*100 -> #DIV/0! | P16: =O16/O$7*100 -> #DIV/0! | Q16: =K16+M16+O16 -> 0 | R16: =Q16/Q$7*100 -> #DIV/0! | T16: =S16/S$7*100 -> #DIV/0! | V16: =U16/U$7*100 -> #DIV/0! | X16: =W16/W$7*100 -> #DIV/0! | Y16: =S16+U16+W16 -> 0 | Z16: =Y16/Y$7*100 -> #DIV/0! | AB16: =AA16/AA$7*100 -> #DIV/0! | AD16: =AC16/AC$7*100 -> #DIV/0! | AF16: =AE16/AE$7*100 -> #DIV/0! | AG16: =AA16+AC16+AE16 -> 0 | AH16: =AG16/AG$7*100 -> #DIV/0!
A17: Материалы | C17: =SUM(C18:C23) -> 0 | D17: =C17/C$7*100 -> #DIV/0! | E17: =SUM(E18:E23) -> 0 | F17: =E17/E$7*100 -> #DIV/0! | G17: =SUM(G18:G23) -> 0 | H17: =G17/G$7*100 -> #DIV/0! | I17: =C17+E17+G17 -> 0 | J17: =I17/I$7*100 -> #DIV/0! | K17: =SUM(K18:K23) -> 0 | L17: =K17/K$7*100 -> #DIV/0! | M17: =SUM(M18:M23) -> 0 | N17: =M17/M$7*100 -> #DIV/0! | O17: =SUM(O18:O23) -> 0 | P17: =O17/O$7*100 -> #DIV/0! | Q17: =K17+M17+O17 -> 0 | R17: =Q17/Q$7*100 -> #DIV/0! | S17: =SUM(S18:S23) -> 0 | T17: =S17/S$7*100 -> #DIV/0! | U17: =SUM(U18:U23) -> 0 | V17: =U17/U$7*100 -> #DIV/0! | W17: =SUM(W18:W23) -> 0 | X17: =W17/W$7*100 -> #DIV/0! | Y17: =S17+U17+W17 -> 0 | Z17: =Y17/Y$7*100 -> #DIV/0! | AA17: =SUM(AA18:AA23) -> 0 | AB17: =AA17/AA$7*100 -> #DIV/0! | AC17: =SUM(AC18:AC23) -> 0 | AD17: =AC17/AC$7*100 -> #DIV/0! | AE17: =SUM(AE18:AE23) -> 0 | AF17: =AE17/AE$7*100 -> #DIV/0! | AG17: =AA17+AC17+AE17 -> 0 | AH17: =AG17/AG$7*100 -> #DIV/0!
A18: Материалы: МБП | D18: =C18/C$7*100 -> #DIV/0! | F18: =E18/E$7*100 -> #DIV/0! | H18: =G18/G$7*100 -> #DIV/0! | I18: =C18+E18+G18 -> 0 | J18: =I18/I$7*100 -> #DIV/0! | L18: =K18/K$7*100 -> #DIV/0! | N18: =M18/M$7*100 -> #DIV/0! | P18: =O18/O$7*100 -> #DIV/0! | Q18: =K18+M18+O18 -> 0 | R18: =Q18/Q$7*100 -> #DIV/0! | T18: =S18/S$7*100 -> #DIV/0! | V18: =U18/U$7*100 -> #DIV/0! | X18: =W18/W$7*100 -> #DIV/0! | Y18: =S18+U18+W18 -> 0 | Z18: =Y18/Y$7*100 -> #DIV/0! | AB18: =AA18/AA$7*100 -> #DIV/0! | AD18: =AC18/AC$7*100 -> #DIV/0! | AF18: =AE18/AE$7*100 -> #DIV/0! | AG18: =AA18+AC18+AE18 -> 0 | AH18: =AG18/AG$7*100 -> #DIV/0!
A19: Материалы: Канцтовары | D19: =C19/C$7*100 -> #DIV/0! | F19: =E19/E$7*100 -> #DIV/0! | H19: =G19/G$7*100 -> #DIV/0! | I19: =C19+E19+G19 -> 0 | J19: =I19/I$7*100 -> #DIV/0! | L19: =K19/K$7*100 -> #DIV/0! | N19: =M19/M$7*100 -> #DIV/0! | P19: =O19/O$7*100 -> #DIV/0! | Q19: =K19+M19+O19 -> 0 | R19: =Q19/Q$7*100 -> #DIV/0! | T19: =S19/S$7*100 -> #DIV/0! | V19: =U19/U$7*100 -> #DIV/0! | X19: =W19/W$7*100 -> #DIV/0! | Y19: =S19+U19+W19 -> 0 | Z19: =Y19/Y$7*100 -> #DIV/0! | AB19: =AA19/AA$7*100 -> #DIV/0! | AD19: =AC19/AC$7*100 -> #DIV/0! | AF19: =AE19/AE$7*100 -> #DIV/0! | AG19: =AA19+AC19+AE19 -> 0 | AH19: =AG19/AG$7*100 -> #DIV/0!
A20: Материалы: Униформа | D20: =C20/C$7*100 -> #DIV/0! | F20: =E20/E$7*100 -> #DIV/0! | H20: =G20/G$7*100 -> #DIV/0! | I20: =C20+E20+G20 -> 0 | J20: =I20/I$7*100 -> #DIV/0! | L20: =K20/K$7*100 -> #DIV/0! | N20: =M20/M$7*100 -> #DIV/0! | P20: =O20/O$7*100 -> #DIV/0! | Q20: =K20+M20+O20 -> 0 | R20: =Q20/Q$7*100 -> #DIV/0! | T20: =S20/S$7*100 -> #DIV/0! | V20: =U20/U$7*100 -> #DIV/0! | X20: =W20/W$7*100 -> #DIV/0! | Y20: =S20+U20+W20 -> 0 | Z20: =Y20/Y$7*100 -> #DIV/0! | AB20: =AA20/AA$7*100 -> #DIV/0! | AD20: =AC20/AC$7*100 -> #DIV/0! | AF20: =AE20/AE$7*100 -> #DIV/0! | AG20: =AA20+AC20+AE20 -> 0 | AH20: =AG20/AG$7*100 -> #DIV/0!
A21: Материалы: Чистящие средства и инвентарь | D21: =C21/C$7*100 -> #DIV/0! | F21: =E21/E$7*100 -> #DIV/0! | H21: =G21/G$7*100 -> #DIV/0! | I21: =C21+E21+G21 -> 0 | J21: =I21/I$7*100 -> #DIV/0! | L21: =K21/K$7*100 -> #DIV/0! | N21: =M21/M$7*100 -> #DIV/0! | P21: =O21/O$7*100 -> #DIV/0! | Q21: =K21+M21+O21 -> 0 | R21: =Q21/Q$7*100 -> #DIV/0! | T21: =S21/S$7*100 -> #DIV/0! | V21: =U21/U$7*100 -> #DIV/0! | X21: =W21/W$7*100 -> #DIV/0! | Y21: =S21+U21+W21 -> 0 | Z21: =Y21/Y$7*100 -> #DIV/0! | AB21: =AA21/AA$7*100 -> #DIV/0! | AD21: =AC21/AC$7*100 -> #DIV/0! | AF21: =AE21/AE$7*100 -> #DIV/0! | AG21: =AA21+AC21+AE21 -> 0 | AH21: =AG21/AG$7*100 -> #DIV/0!
A22: Материалы: Сервис | D22: =C22/C$7*100 -> #DIV/0! | F22: =E22/E$7*100 -> #DIV/0! | H22: =G22/G$7*100 -> #DIV/0! | I22: =C22+E22+G22 -> 0 | J22: =I22/I$7*100 -> #DIV/0! | L22: =K22/K$7*100 -> #DIV/0! | N22: =M22/M$7*100 -> #DIV/0! | P22: =O22/O$7*100 -> #DIV/0! | Q22: =K22+M22+O22 -> 0 | R22: =Q22/Q$7*100 -> #DIV/0! | T22: =S22/S$7*100 -> #DIV/0! | V22: =U22/U$7*100 -> #DIV/0! | X22: =W22/W$7*100 -> #DIV/0! | Y22: =S22+U22+W22 -> 0 | Z22: =Y22/Y$7*100 -> #DIV/0! | AB22: =AA22/AA$7*100 -> #DIV/0! | AD22: =AC22/AC$7*100 -> #DIV/0! | AF22: =AE22/AE$7*100 -> #DIV/0! | AG22: =AA22+AC22+AE22 -> 0 | AH22: =AG22/AG$7*100 -> #DIV/0!
A23: Материалы: Прочие | D23: =C23/C$7*100 -> #DIV/0! | F23: =E23/E$7*100 -> #DIV/0! | H23: =G23/G$7*100 -> #DIV/0! | I23: =C23+E23+G23 -> 0 | J23: =I23/I$7*100 -> #DIV/0! | L23: =K23/K$7*100 -> #DIV/0! | N23: =M23/M$7*100 -> #DIV/0! | P23: =O23/O$7*100 -> #DIV/0! | Q23: =K23+M23+O23 -> 0 | R23: =Q23/Q$7*100 -> #DIV/0! | T23: =S23/S$7*100 -> #DIV/0! | V23: =U23/U$7*100 -> #DIV/0! | X23: =W23/W$7*100 -> #DIV/0! | Y23: =S23+U23+W23 -> 0 | Z23: =Y23/Y$7*100 -> #DIV/0! | AB23: =AA23/AA$7*100 -> #DIV/0! | AD23: =AC23/AC$7*100 -> #DIV/0! | AF23: =AE23/AE$7*100 -> #DIV/0! | AG23: =AA23+AC23+AE23 -> 0 | AH23: =AG23/AG$7*100 -> #DIV/0!
A24: Прочие контролируемые расходы | C24: =C25+C36+C40+C41+C44+C45+C46+C47+C26+C27+C30 -> 0 | D24: =C24/C$7*100 -> #DIV/0! | E24: =E25+E36+E40+E41+E44+E45+E46+E47+E26+E27+E30 -> 0 | F24: =E24/E$7*100 -> #DIV/0! | G24: =G25+G36+G40+G41+G44+G45+G46+G47+G26+G27+G30 -> 0 | H24: =G24/G$7*100 -> #DIV/0! | I24: =C24+E24+G24 -> 0 | J24: =I24/I$7*100 -> #DIV/0! | K24: =K25+K36+K40+K41+K44+K45+K46+K47+K26+K27+K30 -> 0 | L24: =K24/K$7*100 -> #DIV/0! | M24: =M25+M36+M40+M41+M44+M45+M46+M47+M26+M27+M30 -> 0 | N24: =M24/M$7*100 -> #DIV/0! | O24: =O25+O36+O40+O41+O44+O45+O46+O47+O26+O27+O30 -> 0 | P24: =O24/O$7*100 -> #DIV/0! | Q24: =K24+M24+O24 -> 0 | R24: =Q24/Q$7*100 -> #DIV/0! | S24: =S25+S36+S40+S41+S44+S45+S46+S47+S26+S27+S30 -> 0 | T24: =S24/S$7*100 -> #DIV/0! | U24: =U25+U36+U40+U41+U44+U45+U46+U47+U26+U27+U30 -> 0 | V24: =U24/U$7*100 -> #DIV/0! | W24: =W25+W36+W40+W41+W44+W45+W46+W47+W26+W27+W30 -> 0 | X24: =W24/W$7*100 -> #DIV/0! | Y24: =S24+U24+W24 -> 0 | Z24: =Y24/Y$7*100 -> #DIV/0! | AA24: =AA25+AA36+AA40+AA41+AA44+AA45+AA46+AA47+AA26+AA27+AA30 -> 0 | AB24: =AA24/AA$7*100 -> #DIV/0! | AC24: =AC25+AC36+AC40+AC41+AC44+AC45+AC46+AC47+AC26+AC27+AC30 -> 0 | AD24: =AC24/AC$7*100 -> #DIV/0! | AE24: =AE25+AE36+AE40+AE41+AE44+AE45+AE46+AE47+AE26+AE27+AE30 -> 0 | AF24: =AE24/AE$7*100 -> #DIV/0! | AG24: =AA24+AC24+AE24 -> 0 | AH24: =AG24/AG$7*100 -> #DIV/0!
A25: Услуги связи (тел., мобильная связь) | D25: =C25/C$7*100 -> #DIV/0! | F25: =E25/E$7*100 -> #DIV/0! | H25: =G25/G$7*100 -> #DIV/0! | I25: =C25+E25+G25 -> 0 | J25: =I25/I$7*100 -> #DIV/0! | L25: =K25/K$7*100 -> #DIV/0! | N25: =M25/M$7*100 -> #DIV/0! | P25: =O25/O$7*100 -> #DIV/0! | Q25: =K25+M25+O25 -> 0 | R25: =Q25/Q$7*100 -> #DIV/0! | T25: =S25/S$7*100 -> #DIV/0! | V25: =U25/U$7*100 -> #DIV/0! | X25: =W25/W$7*100 -> #DIV/0! | Y25: =S25+U25+W25 -> 0 | Z25: =Y25/Y$7*100 -> #DIV/0! | AB25: =AA25/AA$7*100 -> #DIV/0! | AD25: =AC25/AC$7*100 -> #DIV/0! | AF25: =AE25/AE$7*100 -> #DIV/0! | AG25: =AA25+AC25+AE25 -> 0 | AH25: =AG25/AG$7*100 -> #DIV/0!
B26: Оплата квартиры | D26: =C26/C$7*100 -> #DIV/0! | F26: =E26/E$7*100 -> #DIV/0! | H26: =G26/G$7*100 -> #DIV/0! | I26: =C26+E26+G26 -> 0 | J26: =I26/I$7*100 -> #DIV/0! | L26: =K26/K$7*100 -> #DIV/0! | N26: =M26/M$7*100 -> #DIV/0! | P26: =O26/O$7*100 -> #DIV/0! | Q26: =K26+M26+O26 -> 0 | R26: =Q26/Q$7*100 -> #DIV/0! | T26: =S26/S$7*100 -> #DIV/0! | V26: =U26/U$7*100 -> #DIV/0! | X26: =W26/W$7*100 -> #DIV/0! | Y26: =S26+U26+W26 -> 0 | Z26: =Y26/Y$7*100 -> #DIV/0! | AB26: =AA26/AA$7*100 -> #DIV/0! | AD26: =AC26/AC$7*100 -> #DIV/0! | AF26: =AE26/AE$7*100 -> #DIV/0! | AG26: =AA26+AC26+AE26 -> 0 | AH26: =AG26/AG$7*100 -> #DIV/0!
B27: Транспортно- экспедиционные | D27: =C27/C$7*100 -> #DIV/0! | F27: =E27/E$7*100 -> #DIV/0! | H27: =G27/G$7*100 -> #DIV/0! | I27: =C27+E27+G27 -> 0 | J27: =I27/I$7*100 -> #DIV/0! | L27: =K27/K$7*100 -> #DIV/0! | N27: =M27/M$7*100 -> #DIV/0! | P27: =O27/O$7*100 -> #DIV/0! | Q27: =K27+M27+O27 -> 0 | R27: =Q27/Q$7*100 -> #DIV/0! | T27: =S27/S$7*100 -> #DIV/0! | V27: =U27/U$7*100 -> #DIV/0! | X27: =W27/W$7*100 -> #DIV/0! | Y27: =S27+U27+W27 -> 0 | Z27: =Y27/Y$7*100 -> #DIV/0! | AB27: =AA27/AA$7*100 -> #DIV/0! | AD27: =AC27/AC$7*100 -> #DIV/0! | AF27: =AE27/AE$7*100 -> #DIV/0! | AG27: =AA27+AC27+AE27 -> 0 | AH27: =AG27/AG$7*100 -> #DIV/0!
B28: Такси | D28: =C28/C$7*100 -> #DIV/0! | F28: =E28/E$7*100 -> #DIV/0! | H28: =G28/G$7*100 -> #DIV/0! | L28: =K28/K$7*100 -> #DIV/0! | N28: =M28/M$7*100 -> #DIV/0! | P28: =O28/O$7*100 -> #DIV/0! | T28: =S28/S$7*100 -> #DIV/0! | V28: =U28/U$7*100 -> #DIV/0! | X28: =W28/W$7*100 -> #DIV/0! | AB28: =AA28/AA$7*100 -> #DIV/0! | AD28: =AC28/AC$7*100 -> #DIV/0! | AF28: =AE28/AE$7*100 -> #DIV/0!
B29: Курьер | D29: =C29/C$7*100 -> #DIV/0! | F29: =E29/E$7*100 -> #DIV/0! | H29: =G29/G$7*100 -> #DIV/0! | L29: =K29/K$7*100 -> #DIV/0! | N29: =M29/M$7*100 -> #DIV/0! | P29: =O29/O$7*100 -> #DIV/0! | T29: =S29/S$7*100 -> #DIV/0! | V29: =U29/U$7*100 -> #DIV/0! | X29: =W29/W$7*100 -> #DIV/0! | AB29: =AA29/AA$7*100 -> #DIV/0! | AD29: =AC29/AC$7*100 -> #DIV/0! | AF29: =AE29/AE$7*100 -> #DIV/0!
A30: Информационные услуги | D30: =C30/C$7*100 -> #DIV/0! | F30: =E30/E$7*100 -> #DIV/0! | H30: =G30/G$7*100 -> #DIV/0! | I30: =C30+E30+G30 -> 0 | J30: =I30/I$7*100 -> #DIV/0! | L30: =K30/K$7*100 -> #DIV/0! | N30: =M30/M$7*100 -> #DIV/0! | P30: =O30/O$7*100 -> #DIV/0! | Q30: =K30+M30+O30 -> 0 | R30: =Q30/Q$7*100 -> #DIV/0! | T30: =S30/S$7*100 -> #DIV/0! | V30: =U30/U$7*100 -> #DIV/0! | X30: =W30/W$7*100 -> #DIV/0! | Y30: =S30+U30+W30 -> 0 | Z30: =Y30/Y$7*100 -> #DIV/0! | AB30: =AA30/AA$7*100 -> #DIV/0! | AD30: =AC30/AC$7*100 -> #DIV/0! | AF30: =AE30/AE$7*100 -> #DIV/0! | AG30: =AA30+AC30+AE30 -> 0 | AH30: =AG30/AG$7*100 -> #DIV/0!
B31: интернет | D31: =C31/C$7*100 -> #DIV/0! | F31: =E31/E$7*100 -> #DIV/0! | H31: =G31/G$7*100 -> #DIV/0! | L31: =K31/K$7*100 -> #DIV/0! | N31: =M31/M$7*100 -> #DIV/0! | P31: =O31/O$7*100 -> #DIV/0! | T31: =S31/S$7*100 -> #DIV/0! | V31: =U31/U$7*100 -> #DIV/0! | X31: =W31/W$7*100 -> #DIV/0! | AB31: =AA31/AA$7*100 -> #DIV/0! | AD31: =AC31/AC$7*100 -> #DIV/0! | AF31: =AE31/AE$7*100 -> #DIV/0!
B32: босс-контроль | D32: =C32/C$7*100 -> #DIV/0! | F32: =E32/E$7*100 -> #DIV/0! | H32: =G32/G$7*100 -> #DIV/0! | L32: =K32/K$7*100 -> #DIV/0! | N32: =M32/M$7*100 -> #DIV/0! | P32: =O32/O$7*100 -> #DIV/0! | T32: =S32/S$7*100 -> #DIV/0! | V32: =U32/U$7*100 -> #DIV/0! | X32: =W32/W$7*100 -> #DIV/0! | AB32: =AA32/AA$7*100 -> #DIV/0! | AD32: =AC32/AC$7*100 -> #DIV/0! | AF32: =AE32/AE$7*100 -> #DIV/0!
B33: wi-fi | D33: =C33/C$7*100 -> #DIV/0! | F33: =E33/E$7*100 -> #DIV/0! | H33: =G33/G$7*100 -> #DIV/0! | L33: =K33/K$7*100 -> #DIV/0! | N33: =M33/M$7*100 -> #DIV/0! | P33: =O33/O$7*100 -> #DIV/0! | T33: =S33/S$7*100 -> #DIV/0! | V33: =U33/U$7*100 -> #DIV/0! | X33: =W33/W$7*100 -> #DIV/0! | AB33: =AA33/AA$7*100 -> #DIV/0! | AD33: =AC33/AC$7*100 -> #DIV/0! | AF33: =AE33/AE$7*100 -> #DIV/0!
B34: доставка | D34: =C34/C$7*100 -> #DIV/0! | F34: =E34/E$7*100 -> #DIV/0! | H34: =G34/G$7*100 -> #DIV/0! | L34: =K34/K$7*100 -> #DIV/0! | N34: =M34/M$7*100 -> #DIV/0! | P34: =O34/O$7*100 -> #DIV/0! | T34: =S34/S$7*100 -> #DIV/0! | V34: =U34/U$7*100 -> #DIV/0! | X34: =W34/W$7*100 -> #DIV/0! | AB34: =AA34/AA$7*100 -> #DIV/0! | AD34: =AC34/AC$7*100 -> #DIV/0! | AF34: =AE34/AE$7*100 -> #DIV/0!
B35: обработка фискальных данных | D35: =C35/C$7*100 -> #DIV/0! | F35: =E35/E$7*100 -> #DIV/0! | H35: =G35/G$7*100 -> #DIV/0! | L35: =K35/K$7*100 -> #DIV/0! | N35: =M35/M$7*100 -> #DIV/0! | P35: =O35/O$7*100 -> #DIV/0! | T35: =S35/S$7*100 -> #DIV/0! | V35: =U35/U$7*100 -> #DIV/0! | X35: =W35/W$7*100 -> #DIV/0! | AB35: =AA35/AA$7*100 -> #DIV/0! | AD35: =AC35/AC$7*100 -> #DIV/0! | AF35: =AE35/AE$7*100 -> #DIV/0!
A36: Охранные услуги | D36: =C36/C$7*100 -> #DIV/0! | F36: =E36/E$7*100 -> #DIV/0! | H36: =G36/G$7*100 -> #DIV/0! | I36: =C36+E36+G36 -> 0 | J36: =I36/I$7*100 -> #DIV/0! | L36: =K36/K$7*100 -> #DIV/0! | N36: =M36/M$7*100 -> #DIV/0! | P36: =O36/O$7*100 -> #DIV/0! | Q36: =K36+M36+O36 -> 0 | R36: =Q36/Q$7*100 -> #DIV/0! | T36: =S36/S$7*100 -> #DIV/0! | V36: =U36/U$7*100 -> #DIV/0! | X36: =W36/W$7*100 -> #DIV/0! | Y36: =S36+U36+W36 -> 0 | Z36: =Y36/Y$7*100 -> #DIV/0! | AB36: =AA36/AA$7*100 -> #DIV/0! | AD36: =AC36/AC$7*100 -> #DIV/0! | AF36: =AE36/AE$7*100 -> #DIV/0! | AG36: =AA36+AC36+AE36 -> 0 | AH36: =AG36/AG$7*100 -> #DIV/0!
B37: СБ | D37: =C37/C$7*100 -> #DIV/0! | L37: =K37/K$7*100 -> #DIV/0! | T37: =S37/S$7*100 -> #DIV/0! | AB37: =AA37/AA$7*100 -> #DIV/0!
B38: охранник | D38: =C38/C$7*100 -> #DIV/0! | L38: =K38/K$7*100 -> #DIV/0! | T38: =S38/S$7*100 -> #DIV/0! | AB38: =AA38/AA$7*100 -> #DIV/0!
B39: тех. Обслуживание | D39: =C39/C$7*100 -> #DIV/0! | L39: =K39/K$7*100 -> #DIV/0! | T39: =S39/S$7*100 -> #DIV/0! | AB39: =AA39/AA$7*100 -> #DIV/0!
A40: Командировочные расходы | D40: =C40/C$7*100 -> #DIV/0! | F40: =E40/E$7*100 -> #DIV/0! | H40: =G40/G$7*100 -> #DIV/0! | I40: =C40+E40+G40 -> 0 | J40: =I40/I$7*100 -> #DIV/0! | L40: =K40/K$7*100 -> #DIV/0! | N40: =M40/M$7*100 -> #DIV/0! | P40: =O40/O$7*100 -> #DIV/0! | Q40: =K40+M40+O40 -> 0 | R40: =Q40/Q$7*100 -> #DIV/0! | T40: =S40/S$7*100 -> #DIV/0! | V40: =U40/U$7*100 -> #DIV/0! | X40: =W40/W$7*100 -> #DIV/0! | Y40: =S40+U40+W40 -> 0 | Z40: =Y40/Y$7*100 -> #DIV/0! | AB40: =AA40/AA$7*100 -> #DIV/0! | AD40: =AC40/AC$7*100 -> #DIV/0! | AF40: =AE40/AE$7*100 -> #DIV/0! | AG40: =AA40+AC40+AE40 -> 0 | AH40: =AG40/AG$7*100 -> #DIV/0!
A41: Оценка и соблюдение стандартов | D41: =C41/C$7*100 -> #DIV/0! | F41: =E41/E$7*100 -> #DIV/0! | H41: =G41/G$7*100 -> #DIV/0! | I41: =C41+E41+G41 -> 0 | J41: =I41/I$7*100 -> #DIV/0! | L41: =K41/K$7*100 -> #DIV/0! | N41: =M41/M$7*100 -> #DIV/0! | P41: =O41/O$7*100 -> #DIV/0! | Q41: =K41+M41+O41 -> 0 | R41: =Q41/Q$7*100 -> #DIV/0! | T41: =S41/S$7*100 -> #DIV/0! | V41: =U41/U$7*100 -> #DIV/0! | X41: =W41/W$7*100 -> #DIV/0! | Y41: =S41+U41+W41 -> 0 | Z41: =Y41/Y$7*100 -> #DIV/0! | AB41: =AA41/AA$7*100 -> #DIV/0! | AD41: =AC41/AC$7*100 -> #DIV/0! | AF41: =AE41/AE$7*100 -> #DIV/0! | AG41: =AA41+AC41+AE41 -> 0 | AH41: =AG41/AG$7*100 -> #DIV/0!
B42: GES | D42: =C42/C$7*100 -> #DIV/0! | L42: =K42/K$7*100 -> #DIV/0! | T42: =S42/S$7*100 -> #DIV/0! | AB42: =AA42/AA$7*100 -> #DIV/0!
B43: ROCC | D43: =C43/C$7*100 -> #DIV/0! | L43: =K43/K$7*100 -> #DIV/0! | T43: =S43/S$7*100 -> #DIV/0! | AB43: =AA43/AA$7*100 -> #DIV/0!
...

Sheet СПРАВКА ПО СТАТЬЯМ
B2: Список расходных статей и квалификация счетов
B4: Коммунальные и эксплуатационные услуги
B5: - Природный газ | C5: Газоснабжение
B6: - Электричество | C6: Электроэнергия
B7: - Вода и отопление | C7: Вода и отопление
B8: - Вывоз мусора | C8: Вывоз мусора
B9: - Техобслуж. помещ. | C9: Техобслуж. помещ.
B10: - Клининговые услуги | C10: Клининговые услуги
B11: Материалы
B12: - Инв мат Посуды зала | C12: Не используется
B13: - Инв мат Униформа | C13: Расходы на униформу для сотрудников ресторана
B14: - Инв мат Хозяйственный инвентарь | C14: Порошок фильтрованный "МАГНЕЗОЛ", фильтрованные конверты, списание МБП
B15: - Расх мат Доставка | C15: Не используется
B16: - Расх мат Зал | C16: Не используется
B17: - Расх мат Канцтовары | C17: Заправка картриджа, канцтовары, Этикетлента и Этикет-Пистолет
B18: - Расх мат Кухня | C18: Не используется
B19: - Расх мат Кухонный и барный инвентарь
B20: - Расх мат Одноразовые | C20: Не используется
B21: - Расх мат Прочие | C21: Медикаменты, магнитные карты и все что не входит в другие статьи
B22: - Расх мат Прочий инвентарь
B23: - Расх мат Сервис | C23: Пластиковый поднос, салфетки, пакеты майка, бумажные пакеты, держатели для стаканов, зубочистки, шары с логотипом, белая палочка для шара
B24: - Расх мат Хоз | C24: Средства для мытья посуды, чистки , обезжиривания и дезинфекции оборудовния, мебели, сантехники, полов. Тряпки, щетки, губки, салфетки, бум.полотенца, перчатки, туалетная бумага, халат флисовый, фартук. Комплекты для уборки, ведра
B25: - Расх мат Хозяйственный инвентарь
B26: - Расх мат Чистящие моющие | C26: Чистящие и моющие средства
B27: - Мебель и оборудование малоценка | C27: Мебель и оборудование (малоценка)
B28: Услуги связи (телефонная мобильная связь) | C28: Услуги телефонной связи
B29: Транспортно-экспедиционные расходы | C29: Расходы такси, услуги грузоперевозок и экспедиционные услуги
B30: Ремонт, техобслуживание | C30: Текущие ремонтные работы, техническое обслуживание, профилактика и ремонт оборудования, а так же запчасти к ним.
B31: Командировочные расходы | C31: Проезд, проживание, суточные
B32: Охрана | C32: Охранные услули, техобслуживание средств КТС, средств ОПС, физическая охрана, охрана ПЦО , служба безопасности
B33: Информационные технологии | C33: Услуги интернета, обслуживание ПО, тех.поддержка сайта, программные лицензии Услуги кабельного ТВ, комплектующие к вычислительной технике.
B34: Медкомиссия, санит., лабор. услуги, дезработы | C34: Медкомиссия, санитарно-лабораторные услуги, услуги по дезинфекции и дератизации помещений.
B35: Оплата квартиры | C35: Оплата квартиры
B36: Лицензионная музыка | C36: Музыкально-сервисные сборы
B37: Оценка соблюдения стандартов | C37: Оценка соблюдения стандартов, услуги по проведению аудита от правообладателя
B38: Прочие операционные расходы | C38: Почтовые услуги, услуги химчистки, пособия за счет работодателя
